Workbook

Sheet Sayfa1
A1: 22.06.2021-25.06.2021 BOYABAT BARAJ GÖLÜ STOK TESPİT ÇALIŞMASI SONUÇLARI
A3: 44369 | B3: 1. İSTASYON | C3: 2. İSTASYON | D3: 3. İSTASYON
A4: AV ARACI | B4: 150m boy, 6m derinlik, 70mm göz | C4: 100 boy, 6m derinlik, 60mm göz | D4: 100 boy, 6m derinlik, 60mm göz
A5: KOORDİNAT | B5: 41°19'07.0"N 34°55'08.5"E | C5: 41°18'42.0"N 34°55'22.0"E | D5: 41°19'11.4"N 34°55'48.6"E
A6: TÜRLER | B6: Sazan 1.30 kg, 49cm | C6: Yayın 0.88kg, 48cm | D6: Yayın 1.40 kg, 66cm
B7: sazan 1.23 kg, 46cm | C7: Sazan 1.05kg, 43cm | D7: Sazan 1.28kg, 46cm
B8: Sazan 1.27kg, 47cm | C8: Sazan 1.33kg, 46cm | D8: sazan 1.25kg, 42cm
B9: sazan 1.34kg, 47cm | C9: Sazan 1.56kg, 49cm | D9: Sazan 0.89kg, 40cm
C10: Sudak 2.76kg, 69cm
C11: Sazan 1.29kg, 45cm
C12: Sazan 1.33kg, 46cm
C13: Sazan 1.54kg, 49cm
C14: Sazan 1.47kg, 48cm
C15: Sazan 1.30kg, 45cm
A17: 44370 | B17: 1. İSTASYON | C17: 2. İSTASYON | D17: 3. İSTASYON
A18: AV ARACI | B18: 150m boy, 6m derinlik, 70mm göz | C18: 100 boy, 6m derinlik, 60mm göz | D18: 100 boy, 6m derinlik, 60mm göz
A19: KOORDİNAT | B19: 41°18'48.6"N 34°55'18.1"E | C19: 41°19'09.8"N 34°56'20.5"E | D19: 41°17'29.8"N 34°55'39.0"E
A20: TÜRLER | B20: Sazan 1.08kg, 45cm | C20: Yayın 5.08kg, 89cm | D20: Sazan 1.11kg, 43cm
D21: Sazan 1.79kg, 51cm
D22: Sazan 1.15kg, 44cm
D23: Sazan 1.33kg, 45cm
A25: 24,06,2021 | B25: 1. İSTASYON | C25: 2. İSTASYON | D25: 3. İSTASYON
A26: AV ARACI | B26: 150m boy, 6m derinlik, 70mm göz | C26: 100 boy, 6m derinlik, 60mm göz | D26: 100 boy, 6m derinlik, 60mm göz
A27: KOORDİNAT | B27: 41°17'06.9"N 34°54'49.1"E | C27: 41°17'03.5"N 34°54'24.3"E | D27: 41°16'55.8"N 34°53'59.3"E
A28: TÜRLER | B28: Sazan 1.52kg, 48cm | D28: Yayın 2.99kg, 76cm
A31: Çizelgede verilen tarihler ağların koordinatlara kurulduğu tarihtir.
A32: Çekimler bir sonraki gün saat 08:00-10:00 arasında yapılmıştır.
A33: 22.06.2021 de ağlar akşam saat 18:00 de diğer günler sabah çekimden sonra kurulmuştur.
A34: Diğer günlerde av miktarının az oluşu ağların suda uzun süre kalıp çamur kaplanmasından kaynaklandığı anlaşılmıştır.

Sheet Sayfa2
A1: 22.06.2021-25.06.2021 BOYABAT BARAJ GÖLÜ STOK TESPİT ÇALIŞMASI SONUÇLARI
A3: 44369 | B3: 1. İSTASYON | E3: =+A3 -> 44369 | F3: 1. İSTASYON | I3: =+A3 -> 44369 | J3: 1. İSTASYON
A4: AV ARACI | B4: Boy (m) | C4: Derinlik (m) | D4: Göz Aç.(mm) | E4: AV ARACI | F4: Boy (m) | G4: Derinlik (m) | H4: Göz Aç.(mm) | I4: AV ARACI | J4: Boy (m) | K4: Derinlik (m) | L4: Göz Aç.(mm)
B5: 150 | C5: 6 | D5: 70 | F5: 100 | G5: 6 | H5: 60 | J5: 100 | K5: 6 | L5: 60
A6: KOORDİNAT | B6: 41°19'07.0"N 34°55'08.5"E | E6: KOORDİNAT | F6: 41°18'42.0"N 34°55'22.0"E | I6: KOORDİNAT | J6: 41°19'11.4"N 34°55'48.6"E
A7: TÜRLER | B7: Ağırlık (kg) | D7: Boy (cm) | E7: TÜRLER | F7: Ağırlık (kg) | H7: Boy (cm) | I7: TÜRLER | J7: Ağırlık (kg) | L7: Boy (cm)
A8: Sazan | B8: 1.3 | D8: 49 | E8: Sazan | F8: 1.05 | H8: 43 | I8: Sazan | J8: 1.28 | L8: 46
A9: Sazan | B9: 1.23 | D9: 47 | E9: Sazan | F9: 1.33 | H9: 46 | I9: Sazan | J9: 1.25 | L9: 42
A10: Sazan | B10: 1.34 | D10: 47 | E10: Sazan | F10: 1.56 | H10: 49 | I10: Sazan | J10: 0.89 | L10: 40
A11: Sazan | B11: 1.31 | D11: 45 | E11: Sazan | F11: 1.29 | H11: 45 | I11: Sazan | J11: 1.35 | L11: 45
A12: Sazan | B12: 1.435 | D12: 47 | E12: Sazan | F12: 1.33 | H12: 46 | I12: Sudak | J12: 2.68 | L12: 65
A13: Sudak | B13: 2.71 | D13: 67 | E13: Sazan | F13: 1.54 | H13: 49 | I13: Sudak | J13: 2.56 | L13: 63
A14: Sudak | B14: 2.52 | D14: 61 | E14: Sazan | F14: 1.47 | H14: 48 | I14: Yayın | J14: 1.4 | L14: 66
A15: Yayın | B15: 1.65 | D15: 70 | E15: Sazan | F15: 1.3 | H15: 45
E16: Sudak | F16: 2.76 | H16: 69
E17: Yayın | F17: 0.88 | H17: 48
A18: Toplam | B18: =SUM(B8:C17) -> 13.495 | E18: Toplam | F18: =SUM(F8:G17) -> 14.51 | I18: Toplam | J18: =SUM(J8:K17) -> 11.41
A19: =+B18+F18+J18 -> 39.415
A21: 44370 | B21: 1. İSTASYON | E21: =+A21 -> 44370 | F21: 1. İSTASYON | I21: =+A21 -> 44370 | J21: 1. İSTASYON
A22: AV ARACI | B22: Boy (m) | C22: Derinlik (m) | D22: Göz Aç.(mm) | E22: AV ARACI | F22: Boy (m) | G22: Derinlik (m) | H22: Göz Aç.(mm) | I22: AV ARACI | J22: Boy (m) | K22: Derinlik (m) | L22: Göz Aç.(mm)
B23: 150 | C23: 6 | D23: 70 | F23: 100 | G23: 6 | H23: 60 | J23: 100 | K23: 6 | L23: 60
A24: KOORDİNAT | B24: 41°18'48.6"N 34°55'18.1"E | E24: KOORDİNAT | F24: 41°19'09.8"N 34°56'20.5"E | I24: KOORDİNAT | J24: 41°17'29.8"N 34°55'39.0"E
A25: TÜRLER | B25: Ağırlık (kg) | D25: Boy (cm) | E25: TÜRLER | F25: Ağırlık (kg) | H25: Boy (cm) | I25: TÜRLER | J25: Ağırlık (kg) | L25: Boy (cm)
A26: Sazan | B26: 1.08 | D26: 45 | E26: Sazan | F26: 1.54 | H26: 48 | I26: Sazan | J26: 1.11 | L26: 43
A27: Sazan | B27: 1.36 | D27: 47 | E27: Sazan | F27: 1.31 | H27: 46 | I27: Sazan | J27: 1.79 | L27: 51
A28: Sazan | B28: 1.45 | D28: 48 | E28: Sazan | F28: 1.43 | H28: 47 | I28: Sazan | J28: 1.15 | L28: 44
A29: Sazan | B29: 1.51 | D29: 47 | E29: Sazan | F29: 1.28 | H29: 45 | I29: Sazan | J29: 1.33 | L29: 45
A30: Sudak | B30: 2.61 | D30: 64 | E30: Sudak | F30: 2.53 | H30: 63 | I30: Yayın | J30: 1.83 | L30: 72
A31: Yayın | B31: 2.7 | D31: 75 | E31: Yayın | F31: 5.08 | H31: 89
A32: Yayın | B32: 1.76 | D32: 70
A36: Toplam | B36: =+SUM(B26:B35) -> 12.47 | E36: Toplam | F36: =SUM(F26:G35) -> 13.17 | I36: Toplam | J36: =SUM(J26:K35) -> 7.21
A37: =+B36+F36+J36 -> 32.85
A39: 44371 | B39: 1. İSTASYON | E39: =+A39 -> 44371 | F39: 1. İSTASYON | I39: =+A39 -> 44371 | J39: 1. İSTASYON
A40: AV ARACI | B40: Boy (m) | C40: Derinlik (m) | D40: Göz Aç.(mm) | E40: AV ARACI | F40: Boy (m) | G40: Derinlik (m) | H40: Göz Aç.(mm) | I40: AV ARACI | J40: Boy (m) | K40: Derinlik (m) | L40: Göz Aç.(mm)
B41: 150 | C41: 6 | D41: 70 | F41: 100 | G41: 6 | H41: 60 | J41: 100 | K41: 6 | L41: 60
A42: KOORDİNAT | B42: 41°17'06.9"N 34°54'49.1"E | E42: KOORDİNAT | F42: 41°17'03.5"N 34°54'24.3"E | I42: KOORDİNAT | J42: 41°16'55.8"N 34°53'59.3"E
A43: TÜRLER | B43: Ağırlık (kg) | D43: Boy (cm) | E43: TÜRLER | F43: Ağırlık (kg) | H43: Boy (cm) | I43: TÜRLER | J43: Ağırlık (kg) | L43: Boy (cm)
A44: Sazan | B44: 1.52 | D44: 48 | E44: Sazan | F44: 1.34 | H44: 48 | I44: Sazan | J44: 1.25 | L44: 43
A45: Sazan | B45: 1.31 | D45: 47 | E45: Sazan | F45: 1.31 | H45: 47 | I45: Sazan | J45: 1.67 | L45: 49
A46: Sazan | B46: 1.27 | D46: 46 | E46: Sazan | F46: 1.47 | H46: 45 | I46: Sazan | J46: 1.52 | L46: 47
...

Sheet Sonuç
A1: ….. Baraj Gölü | D1: 671km2 | E1: 671000000 | F1: m2
A2: Balıkçı Sayısı | D2: 200
A3: Ticari Türler | D3: C. Carpio (2 tür), Luciobarbus esocinus, Luciobarbus xanthopterus, Luciobarbus mystaceus. Capoeta trutta, Oncorhynchus mykiss. Capoeta umbla vs…
L5: Avlanan Miktarlar (kg) | O5: Birim alandaki stok yoğunluğu (kg/m2) | R5: Toplam Stok (kg)
A6: Ağlar | B6: Ağ göz açıklığı (mm) | C6: Ağ uzunluğu (m) | D6: Derinlik Göz Sayısı (adet) | E6: Ağın Derinliği (m) | F6: Ağın Alanı (m2) | G6: Tüm Ağların Alanı (m2) | I6: Avcılık No: | J6: Avcılık Tarihi | K6: Ağların alanı (m2) | L6: 1. İst. | M6: 2. ist. | N6: 3. ist. | O6: 1. İst. | P6: 2. ist. | Q6: 3. ist. | R6: 1. İst. | S6: 2. ist. | T6: 3. ist.
B7: =+Sayfa2!D5 -> 70 | C7: =+Sayfa2!B5 -> 150 | E7: =+Sayfa2!C5 -> 6 | F7: =C7*E7 -> 900 | G7: =SUM(F7:F13) -> 2100 | J7: =+Sayfa2!A3 -> 44369 | K7: =G7 -> 2100 | L7: =+Sayfa2!B18 -> 13.495 | M7: =+Sayfa2!F18 -> 14.51 | N7: =+Sayfa2!J18 -> 11.41 | O7: =L7/$K$7 -> 0.0064261905 | P7: =M7/$K$7 -> 0.0069095238 | Q7: =N7/$K$7 -> 0.0054333333 | R7: =O7*$C$17 -> 1349500 | S7: =P7*$C$18 -> 1589190.5 | T7: =Q7*$C$19 -> 1255100
B8: =+Sayfa2!H5 -> 60 | C8: =+Sayfa2!F5 -> 100 | E8: =+Sayfa2!G5 -> 6 | F8: =C8*E8 -> 600 | J8: =+Sayfa2!A21 -> 44370 | L8: =+Sayfa2!B36 -> 12.47 | M8: =+Sayfa2!F36 -> 13.17 | N8: =+Sayfa2!J36 -> 7.21 | O8: =L8/$K$7 -> 0.0059380952 | P8: =M8/$K$7 -> 0.0062714286 | Q8: =N8/$K$7 -> 0.0034333333 | R8: =O8*$C$17 -> 1247000 | S8: =P8*$C$18 -> 1442428.6 | T8: =Q8*$C$19 -> 793100
B9: =+Sayfa2!L5 -> 60 | C9: =+Sayfa2!J5 -> 100 | E9: =+Sayfa2!K5 -> 6 | F9: =C9*E9 -> 600 | J9: =+Sayfa2!A39 -> 44371 | L9: =+Sayfa2!B54 -> 10.02 | M9: =+Sayfa2!F54 -> 9.04 | N9: =+Sayfa2!J54 -> 10.76 | O9: =L9/$K$7 -> 0.0047714286 | P9: =M9/$K$7 -> 0.0043047619 | Q9: =N9/$K$7 -> 0.0051238095 | R9: =O9*$C$17 -> 1002000 | S9: =P9*$C$18 -> 990095.24 | T9: =Q9*$C$19 -> 1183600
E10: =B10*D10*0.866/1000 -> 0 | F10: =C10*E10 -> 0 | O10: =L10/$K$7 -> 0 | P10: =M10/$K$7 -> 0 | Q10: =N10/$K$7 -> 0 | R10: =O10*$C$17 -> 0 | S10: =P10*$C$18 -> 0 | T10: =Q10*$C$19 -> 0
E11: =B11*D11*0.866/1000 -> 0 | F11: =C11*E11 -> 0 | O11: =L11/$K$7 -> 0 | P11: =M11/$K$7 -> 0 | Q11: =N11/$K$7 -> 0 | R11: =O11*$C$17 -> 0 | S11: =P11*$C$18 -> 0 | T11: =Q11*$C$19 -> 0
E12: =B12*D12*0.866/1000 -> 0 | F12: =C12*E12 -> 0 | O12: =L12/$K$7 -> 0 | P12: =M12/$K$7 -> 0 | Q12: =N12/$K$7 -> 0 | R12: =O12*$C$17 -> 0 | S12: =P12*$C$18 -> 0 | T12: =Q12*$C$19 -> 0
E13: =B13*D13*0.866/1000 -> 0 | F13: =C13*E13 -> 0 | O13: =L13/$K$7 -> 0 | P13: =M13/$K$7 -> 0 | Q13: =N13/$K$7 -> 0 | R13: =O13*$C$17 -> 0 | S13: =P13*$C$18 -> 0 | T13: =Q13*$C$19 -> 0
O14: =L14/$K$7 -> 0 | P14: =M14/$K$7 -> 0 | Q14: =N14/$K$7 -> 0 | R14: =O14*$C$17 -> 0 | S14: =P14*$C$18 -> 0 | T14: =Q14*$C$19 -> 0
O15: =L15/$K$7 -> 0 | P15: =M15/$K$7 -> 0 | Q15: =N15/$K$7 -> 0 | R15: =O15*$C$17 -> 0 | S15: =P15*$C$18 -> 0 | T15: =Q15*$C$19 -> 0
B16: İstasyonların alanları (km2) | O16: =L16/$K$7 -> 0 | P16: =M16/$K$7 -> 0 | Q16: =N16/$K$7 -> 0 | R16: =O16*$C$17 -> 0 | S16: =P16*$C$18 -> 0 | T16: =Q16*$C$19 -> 0
A17: 1. İst | B17: 210 km2 | C17: =210*1000000 -> 210000000 | D17: m2 | I17: Ortalama (kg) | L17: =AVERAGE(L7:L16) -> 11.995 | M17: =AVERAGE(M7:M16) -> 12.24 | N17: =AVERAGE(N7:N16) -> 9.7933333 | O17: =L17/$K$7 -> 0.0057119048 | P17: =M17/$K$7 -> 0.0058285714 | Q17: =N17/$K$7 -> 0.0046634921 | R17: =O17*$C$17 -> 1199500 | S17: =P17*$C$18 -> 1340571.4 | T17: =Q17*$C$19 -> 1077266.7
A18: 2. ist | B18: 230 km2 | C18: 230000000 | D18: m2 | I18: Toplam Biyomas (ton) | R18: =SUM(R17:T17)/1000 -> 3617.3381
A19: 3. ist | B19: 231 km2 | C19: 231000000 | D19: m2
I21: E= 0,3 ile 0,6 arasında tercih edilebilir, ideal değeri 0,5 olarak kabul edilir | T21: Avlanan Miktarlar (kg) | U21: Türlerin toplam avdaki oranları
A22: 0.866 | B22: 0,5 donam faktörüyle donanmış bir ağın derinliğini hesaplamak için kullanılan sabit katsayı | I22: E=0,5 alınırsa | L22: Avlanabilir Stok (kiralamaya esas) = | P22: =R18*0.5 -> 1808.669
I23: E=0,3 alınırsa | L23: Avlanabilir Stok (kiralamaya esas) = | P23: =R18*0.3 -> 1085.2014 | S23: C.carpio (aynalı) | T23: 30 | U23: =T23*100/T$30 -> 16
I24: E=0,4 alınırsa | L24: Avlanabilir Stok (kiralamaya esas) = | P24: =R18*0.4 -> 1446.9352 | S24: C.carpio(pullu) | T24: 35 | U24: =T24*100/T$30 -> 18.666667
S25: L.esocinus | T25: 22 | U25: =T25*100/T$30 -> 11.733333
S26: O.mykiss | T26: 23.5 | U26: =T26*100/T$30 -> 12.533333
C27: NOT: Sonuçta her bir tür için ayrı bir stok hesaplayacaksak eğer her avcılıkta yakaladığımız balıkların ağırlıkça oranlarını tespit etmemiz lazım. Böylece toplamda şu kadar avcılık yaptık şu akdar kilo balık yakaladık bunun %20 si şu türdendi dolayısıyla tespit ettiğimiz stoktaki oranıda budur diyebiliriz. | S27: C.umbla | T27: 24 | U27: =T27*100/T$30 -> 12.8
S28: C.trutta | T28: 18 | U28: =T28*100/T$30 -> 9.6
S29: L.mystaceus | T29: 35 | U29: =T29*100/T$30 -> 18.666667
S30: Toplam | T30: =SUM(T23:T29) -> 187.5 | U30: =SUM(U23:U29) -> 100
F31: Rapor örneği
B32: Baraj gölünün …. Avlaksahalarında belirlenen … istasyonda …. - … göz açıklığına sahip … adet uzatma ağları kullanılarak ….. İle ….. Tarihleri arasında avcılık operasyonları düzenlenmiştir. Denemeler sonucunda ………. türlerinden toplam …. Kg balık yakalanmış olup toplam avın ağırlığına göre dağılımı ise şu şekildedir. ... türü %...., ... türü: 5... vs. Stok büyüklüğünün tahmininde Avşar ve diğ. (2000)’in önerdiği “Uzatma Ağlarıyla Avcılık Yöntemi”nden yararlanılmıştır. her bir bölge için hesaplanan toplam stok değerleri tabloda görülmektedir. (stokların hesaplandığı tablo rapora konabilir). Ayrıca baraj gölündeki avcılık baskısı ya da ..... faktörler dikkate alındığında stoktan yararlanma düzeyinin Gulland (1971), E= .... olarak alınması uygun bulunmaktadır bu durumda yıllık kiralamaya esas stok miktarı .... ton/yıl olarak tahmin edilmiştir.
B42: Gulland, 1971. The Fish Resources of the Ocean. West By fleet, Surrey, Fishing News (Books) Ltd., England.
B43: Avşar, D., C. E. Özyurt, E. Çiçek, H. Yeldan, M. Özütok, 2000. A Study on the Biomass Estimation of the Carp (Cyprinus carpio, Linnaeus, 1758) and Pike-Perch (Sander lucioperca, Bogustkaya&Naseka, 1996) Inhabiting in Seyhan Dam Lake (in Turkish). XI. Ulusal Su Ürünleri Sempozyumu, 4-6 Eylül 2001, Hatay, 103-118.
B44: Bunları da raporun altına kaynak olarak ekleyebilirsiniz

Sheet Sayfa3
A1: 22.06.2021-25.06.2021 BOYABAT BARAJ GÖLÜ STOK TESPİT ÇALIŞMASI SONUÇLARI
A4: 44369 | B4: 1. İSTASYON | D4: 2. İSTASYON | G4: 3. İSTASYON
A5: AV ARACI | B5: 150m boy, 6m derinlik, 70mm göz | D5: AV ARACI | E5: 100m boy, 6m derinlik, 60mm göz | G5: AV ARACI | H5: 100m boy, 6m derinlik, 60mm göz
A6: KOORDİNAT | B6: 41°19'07.0"N 34°55'08.5"E | D6: KOORDİNAT | E6: 41°18'42.0"N 34°55'22.0"E | G6: KOORDİNAT | H6: 41°19'11.4"N 34°55'48.6"E
A7: TÜRLER | B7: Ağırlık (kg) | C7: Boy (cm) | D7: TÜRLER | E7: Ağırlık (kg) | F7: Boy (cm) | G7: TÜRLER | H7: Ağırlık (kg) | I7: Boy (cm)
A8: Sazan | B8: 1.3 | C8: 49 | D8: Sazan | E8: 1.05 | F8: 43 | G8: Sazan | H8: 1.28 | I8: 46
A9: Sazan | B9: 1.23 | C9: 47 | D9: Sazan | E9: 1.33 | F9: 46 | G9: Sazan | H9: 1.25 | I9: 42
A10: Sazan | B10: 1.34 | C10: 47 | D10: Sazan | E10: 1.56 | F10: 49 | G10: Sazan | H10: 0.89 | I10: 40
D11: Sazan | E11: 1.29 | F11: 45 | G11: Yayın | H11: 1.4 | I11: 66
D12: Sazan | E12: 1.33 | F12: 46
D13: Sazan | E13: 1.54 | F13: 49
D14: Sazan | E14: 1.47 | F14: 48
D15: Sazan | E15: 1.3 | F15: 45
D16: Sudak | E16: 2.76 | F16: 69
D17: Yayın | E17: 0.88 | F17: 48
A20: Toplam | B20: =+SUM(B8:B19) -> 3.87 | D20: Toplam | E20: =+SUM(E8:E19) -> 14.51 | G20: Toplam | H20: =+SUM(H8:H19) -> 4.82
A21: =+B20+E20+H20 -> 23.2
A23: 44370 | B23: 1. İSTASYON | D23: 2. İSTASYON | G23: 3. İSTASYON
A24: AV ARACI | B24: 150m boy, 6m derinlik, 70mm göz | D24: AV ARACI | E24: 100m boy, 6m derinlik, 60mm göz | G24: AV ARACI | H24: 100m boy, 6m derinlik, 60mm göz
A25: KOORDİNAT | B25: 41°18'48.6"N 34°55'18.1"E | D25: KOORDİNAT | E25: 41°19'09.8"N 34°56'20.5"E | G25: KOORDİNAT | H25: 41°17'29.8"N 34°55'39.0"E
A26: TÜRLER | B26: Ağırlık (kg) | C26: Boy (cm) | D26: TÜRLER | E26: Ağırlık (kg) | F26: Boy (cm) | G26: TÜRLER | H26: Ağırlık (kg) | I26: Boy (cm)
A27: Sazan | B27: 1.08 | C27: 45 | D27: Yayın | E27: 5.08 | F27: 89 | G27: Sazan | H27: 1.11 | I27: 43
G28: Sazan | H28: 1.79 | I28: 51
G29: Sazan | H29: 1.15 | I29: 44
G30: Sazan | H30: 1.33 | I30: 45
A39: Toplam | B39: =+SUM(B27:B38) -> 1.08 | D39: Toplam | E39: =+SUM(E27:E38) -> 5.08 | G39: Toplam | H39: =+SUM(H27:H38) -> 5.38
A40: =+B39+E39+H39 -> 11.54
A42: 44370 | B42: 1. İSTASYON | D42: 2. İSTASYON | G42: 3. İSTASYON
A43: AV ARACI | B43: 150m boy, 6m derinlik, 70mm göz | D43: AV ARACI | E43: 100m boy, 6m derinlik, 60mm göz | G43: AV ARACI | H43: 100m boy, 6m derinlik, 60mm göz
A44: KOORDİNAT | B44: 41°17'06.9"N 34°54'49.1"E | D44: KOORDİNAT | E44: 41°17'03.5"N 34°54'24.3"E | G44: KOORDİNAT | H44: 41°16'55.8"N 34°53'59.3"E
A45: TÜRLER | B45: Ağırlık (kg) | C45: Boy (cm) | D45: TÜRLER | E45: Ağırlık (kg) | F45: Boy (cm) | G45: TÜRLER | H45: Ağırlık (kg) | I45: Boy (cm)
A46: Sazan | B46: 1.52 | C46: 48 | G46: Yayın | H46: 2.99 | I46: 76
A58: Toplam | B58: =+SUM(B46:B57) -> 1.52 | D58: Toplam | E58: =+SUM(E46:E57) -> 0 | G58: Toplam | H58: =+SUM(H46:H57) -> 2.99
A59: =+B58+E58+H58 -> 4.51
A61: Çizelgede verilen tarihler ağların koordinatlara kurulduğu tarihtir.
A62: Çekimler bir sonraki gün saat 08:00-10:00 arasında yapılmıştır.
A63: 22.06.2021 de ağlar akşam saat 18:00 de diğer günler sabah çekimden sonra kurulmuştur.
A64: Diğer günlerde av miktarının az oluşu ağların suda uzun süre kalıp çamur kaplanmasından kaynaklandığı anlaşılmıştır.
