Workbook

Sheet Sayfa2
A1: 22.06.2021-25.06.2021 BOYABAT BARAJ GÖLÜ STOK TESPİT ÇALIŞMASI SONUÇLARI
A3: 22.06.2021 | B3: 1. İSTASYON | E3: =+A3 -> 22.06.2021 | F3: 2. İSTASYON | I3: =+A3 -> 22.06.2021 | J3: 3. İSTASYON
A4: AV ARACI | B4: Boy (m) | C4: Derinlik (m) | D4: Göz Aç.(mm) | E4: AV ARACI | F4: Boy (m) | G4: Derinlik (m) | H4: Göz Aç.(mm) | I4: AV ARACI | J4: Boy (m) | K4: Derinlik (m) | L4: Göz Aç.(mm)
B5: 150 | C5: 6 | D5: 70 | F5: 100 | G5: 6 | H5: 60 | J5: 100 | K5: 6 | L5: 60
A6: KOORDİNAT | B6: 41°19'07.0"N 34°55'08.5"E | E6: KOORDİNAT | F6: 41°18'42.0"N 34°55'22.0"E | I6: KOORDİNAT | J6: 41°19'11.4"N 34°55'48.6"E
A7: TÜRLER | B7: Ağırlık (kg) | D7: Boy (cm) | E7: TÜRLER | F7: Ağırlık (kg) | H7: Boy (cm) | I7: TÜRLER | J7: Ağırlık (kg) | L7: Boy (cm)
A8: Sazan | B8: 1.3 | D8: 49 | E8: Sazan | F8: 1.05 | H8: 43 | I8: Sazan | J8: 1.28 | L8: 46
A9: Sazan | B9: 1.23 | D9: 47 | E9: Sazan | F9: 1.33 | H9: 46
A14: Sudak | B14: 2.52 | D14: 61
A15: Yayın | B15: 1.65 | D15: 70
E17: Yayın | F17: 0.88 | H17: 48
A18: Toplam | B18: =SUM(B8:C17) -> 6.7 | E18: Toplam | F18: =SUM(F8:G17) -> 3.26 | I18: Toplam | J18: =SUM(J8:K17) -> 1.28
A19: =+B18+F18+J18 -> 11.24
A21: 23.06.2021 | B21: 1. İSTASYON | E21: =+A21 -> 23.06.2021 | F21: 2. İSTASYON | I21: =+A21 -> 23.06.2021 | J21: 3. İSTASYON
A22: AV ARACI | B22: Boy (m) | C22: Derinlik (m) | D22: Göz Aç.(mm) | E22: AV ARACI | F22: Boy (m) | G22: Derinlik (m) | H22: Göz Aç.(mm) | I22: AV ARACI | J22: Boy (m) | K22: Derinlik (m) | L22: Göz Aç.(mm)
B23: 150 | C23: 6 | D23: 70 | F23: 100 | G23: 6 | H23: 60 | J23: 100 | K23: 6 | L23: 60
A24: KOORDİNAT | B24: 41°18'48.6"N 34°55'18.1"E | E24: KOORDİNAT | F24: 41°19'09.8"N 34°56'20.5"E | I24: KOORDİNAT | J24: 41°17'29.8"N 34°55'39.0"E
A25: TÜRLER | B25: Ağırlık (kg) | D25: Boy (cm) | E25: TÜRLER | F25: Ağırlık (kg) | H25: Boy (cm) | I25: TÜRLER | J25: Ağırlık (kg) | L25: Boy (cm)
A26: Sazan | B26: 1.08 | D26: 45 | E26: Sazan | F26: 1.54 | H26: 48 | I26: Sazan | J26: 1.11 | L26: 43
A27: Sazan | B27: 1.36 | D27: 47 | E27: Sazan | F27: 1.31 | H27: 46 | I27: Sazan | J27: 1.79 | L27: 51
A28: Siraz | B28: 0.2 | D28: 22 | E28: Tatlısu kefali | F28: 0.6 | H28: 30
A29: Sudak | B29: 2.61 | D29: 64
A30: Yayın | B30: 2.7 | D30: 75 | I30: Yayın | J30: 1.83 | L30: 72
P31: Siraz
P32: Tatlısu kefali
P33: Bıyıklı balık
A36: Toplam | B36: =+SUM(B26:B35) -> 7.95 | E36: Toplam | F36: =SUM(F26:G35) -> 3.45 | I36: Toplam | J36: =SUM(J26:K35) -> 4.73
A37: =+B36+F36+J36 -> 16.13
A39: 24.06.2021 | B39: 1. İSTASYON | E39: =+A39 -> 24.06.2021 | F39: 2. İSTASYON | I39: =+A39 -> 24.06.2021 | J39: 3. İSTASYON
A40: AV ARACI | B40: Boy (m) | C40: Derinlik (m) | D40: Göz Aç.(mm) | E40: AV ARACI | F40: Boy (m) | G40: Derinlik (m) | H40: Göz Aç.(mm) | I40: AV ARACI | J40: Boy (m) | K40: Derinlik (m) | L40: Göz Aç.(mm)
B41: 150 | C41: 6 | D41: 70 | F41: 100 | G41: 6 | H41: 60 | J41: 100 | K41: 6 | L41: 60
A42: KOORDİNAT | B42: 41°17'06.9"N 34°54'49.1"E | E42: KOORDİNAT | F42: 41°17'03.5"N 34°54'24.3"E | I42: KOORDİNAT | J42: 41°16'55.8"N 34°53'59.3"E
A43: TÜRLER | B43: Ağırlık (kg) | D43: Boy (cm) | E43: TÜRLER | F43: Ağırlık (kg) | H43: Boy (cm) | I43: TÜRLER | J43: Ağırlık (kg) | L43: Boy (cm)
A44: Sazan | B44: 1.52 | D44: 48 | E44: Sazan | F44: 1.34 | H44: 48 | I44: Sazan | J44: 1.25 | L44: 43
A45: Sazan | B45: 1.31 | D45: 47 | E45: Sazan | F45: 1.31 | H45: 47 | I45: Sazan | J45: 1.67 | L45: 49
E47: Sudak | F47: 2.4 | H47: 63
A49: Yayın | B49: 2.1 | D49: 71 | I49: Yayın | J49: 2.99 | L49: 76
A54: Toplam | B54: =+SUM(B44:B53) -> 4.93 | E54: Toplam | F54: =SUM(F44:G53) -> 5.05 | I54: Toplam | J54: =SUM(J44:K53) -> 5.91
A55: =+B54+F54+J54 -> 15.89
A57: Çizelgede verilen tarihler ağların koordinatlara kurulduğu tarihtir.
...

Sheet Sonuç
B1: İstasyonların alanları (km2) | E1: Saraydüzü Boyabat Baraj Gölü | H1: =+I1/1000000 -> 20 | I1: =+C2+C3+C4 -> 20000000
A2: 1. İst | B2: 7 | C2: =+B2*1000000 -> 7000000 | E2: Balıkçı Sayısı | H2: 200
A3: 2. ist | B3: 7 | C3: =+B3*1000000 -> 7000000 | E3: Ticari Türler | H3: =+CONCATENATE(B35,",",B36,",",B37,",",B38,",",B39,",",B40," ,",B41," ","vs.") -> C.carpio,S. glanis,S. lucioperca,Capoeta sp.,S.cephalus,Barbus sp. ,P.marmoratus vs.
A4: 3. ist | B4: 6 | C4: =+B4*1000000 -> 6000000
A6: Ağlar | B6: Ağ göz açıklığı (mm) | C6: Ağ uzunluğu (m) | D6: Derinlik Göz Sayısı (adet) | E6: Ağın Derinliği (m) | F6: Ağın Alanı (m2) | G6: Tüm Ağların Alanı (m2)
A7: 1 | B7: =+Sayfa2!D5 -> 70 | C7: =+Sayfa2!B5 -> 150 | E7: =+Sayfa2!C5 -> 6 | F7: =C7*E7 -> 900 | G7: =SUM(F7:F9) -> 2100
A8: 2 | B8: =+Sayfa2!H5 -> 60 | C8: =+Sayfa2!F5 -> 100 | E8: =+Sayfa2!G5 -> 6 | F8: =C8*E8 -> 600
A9: 3 | B9: =+Sayfa2!L5 -> 60 | C9: =+Sayfa2!J5 -> 100 | E9: =+Sayfa2!K5 -> 6 | F9: =C9*E9 -> 600
B10: =+ROUND(AVERAGE(B7:B9),0) -> 63
D11: Avlanan Miktarlar (kg) | G11: Birim alandaki stok yoğunluğu (kg/m2) | J11: Toplam Stok (kg)
A12: Avcılık No: | B12: Avcılık Tarihi | C12: Ağların alanı (m2) | D12: 1. İst. | E12: 2. ist. | F12: 3. ist. | G12: 1. İst. | H12: 2. ist. | I12: 3. ist. | J12: 1. İst. | K12: 2. ist. | L12: 3. ist.
B13: =+Sayfa2!A3 -> 22.06.2021 | C13: =G7 -> 2100 | D13: =+Sayfa2!B18 -> 6.7 | E13: =+Sayfa2!F18 -> 3.26 | F13: =+Sayfa2!J18 -> 1.28 | G13: =D13/$C$13 -> 0.0031904762 | H13: =E13/$C$13 -> 0.001552381 | I13: =F13/$C$13 -> 0.00060952381 | J13: =G13*$C$2 -> 22333.333 | K13: =H13*$C$3 -> 10866.667 | L13: =I13*$C$4 -> 3657.1429
B14: =+Sayfa2!A21 -> 23.06.2021 | D14: =+Sayfa2!B36 -> 7.95 | E14: =+Sayfa2!F36 -> 3.45 | F14: =+Sayfa2!J36 -> 4.73 | G14: =D14/$C$13 -> 0.0037857143 | H14: =E14/$C$13 -> 0.0016428571 | I14: =F14/$C$13 -> 0.002252381 | J14: =G14*$C$2 -> 26500 | K14: =H14*$C$3 -> 11500 | L14: =I14*$C$4 -> 13514.286
B15: =+Sayfa2!A39 -> 24.06.2021 | D15: =+Sayfa2!B54 -> 4.93 | E15: =+Sayfa2!F54 -> 5.05 | F15: =+Sayfa2!J54 -> 5.91 | G15: =D15/$C$13 -> 0.002347619 | H15: =E15/$C$13 -> 0.0024047619 | I15: =F15/$C$13 -> 0.0028142857 | J15: =G15*$C$2 -> 16433.333 | K15: =H15*$C$3 -> 16833.333 | L15: =I15*$C$4 -> 16885.714
G16: =D16/$C$13 -> 0 | H16: =E16/$C$13 -> 0 | I16: =F16/$C$13 -> 0 | J16: =G16*$C$2 -> 0 | K16: =H16*$C$3 -> 0 | L16: =I16*$C$4 -> 0
G17: =D17/$C$13 -> 0 | H17: =E17/$C$13 -> 0 | I17: =F17/$C$13 -> 0 | J17: =G17*$C$2 -> 0 | K17: =H17*$C$3 -> 0 | L17: =I17*$C$4 -> 0
G18: =D18/$C$13 -> 0 | H18: =E18/$C$13 -> 0 | I18: =F18/$C$13 -> 0 | J18: =G18*$C$2 -> 0 | K18: =H18*$C$3 -> 0 | L18: =I18*$C$4 -> 0
G19: =D19/$C$13 -> 0 | H19: =E19/$C$13 -> 0 | I19: =F19/$C$13 -> 0 | J19: =G19*$C$2 -> 0 | K19: =H19*$C$3 -> 0 | L19: =I19*$C$4 -> 0
G20: =D20/$C$13 -> 0 | H20: =E20/$C$13 -> 0 | I20: =F20/$C$13 -> 0 | J20: =G20*$C$2 -> 0 | K20: =H20*$C$3 -> 0 | L20: =I20*$C$4 -> 0
G21: =D21/$C$13 -> 0 | H21: =E21/$C$13 -> 0 | I21: =F21/$C$13 -> 0 | J21: =G21*$C$2 -> 0 | K21: =H21*$C$3 -> 0 | L21: =I21*$C$4 -> 0
G22: =D22/$C$13 -> 0 | H22: =E22/$C$13 -> 0 | I22: =F22/$C$13 -> 0 | J22: =G22*$C$2 -> 0 | K22: =H22*$C$3 -> 0 | L22: =I22*$C$4 -> 0
A23: Ortalama (kg) | D23: =AVERAGE(D13:D22) -> 6.5266667 | E23: =AVERAGE(E13:E22) -> 3.92 | F23: =AVERAGE(F13:F22) -> 3.9733333 | G23: =D23/$C$13 -> 0.0031079365 | H23: =E23/$C$13 -> 0.0018666667 | I23: =F23/$C$13 -> 0.0018920635 | J23: =G23*$C$2 -> 21755.556 | K23: =H23*$C$3 -> 13066.667 | L23: =I23*$C$4 -> 11352.381
A24: Toplam Biyomas (ton) | J24: =SUM(J23:L23)/1000 -> 46.174603
A27: 0.866 | B27: 0,5 donam faktörüyle donanmış bir ağın derinliğini hesaplamak için kullanılan sabit katsayı | F27: E= 0,3 ile 0,6 arasında tercih edilebilir, ideal değeri 0,5 olarak kabul edilir
F28: E=0,5 | G28: alınırsa | H28: Avlanabilir Stok (kiralamaya esas) = | K28: =J24*0.5 -> 23.087302 | L28: =+ROUND(K28,4) -> 23.0873
F29: E=0,3 | G29: alınırsa | H29: Avlanabilir Stok (kiralamaya esas) = | K29: =J24*0.3 -> 13.852381 | L29: =+ROUND(K29,4) -> 13.8524
F30: E=0,4 | G30: alınırsa | H30: Avlanabilir Stok (kiralamaya esas) = | K30: =J24*0.4 -> 18.469841
C33: Avlanan Miktarlar (kg) | D33: Türlerin toplam avdaki oranları
A35: Sazan | B35: C.carpio | C35: =+SUMIFS(Sayfa2!$B:$B,Sayfa2!A:A,A35)+SUMIFS(Sayfa2!F:F,Sayfa2!E:E,A35)+SUMIFS(Sayfa2!J:J,Sayfa2!I:I,A35) -> 22.78 | D35: =C35/C$42*100 -> 52.658345 | E35: =+IF(C35>0.01,1,0) -> 1
A36: Yayın | B36: S. glanis | C36: =+SUMIFS(Sayfa2!$B:$B,Sayfa2!A:A,A36)+SUMIFS(Sayfa2!F:F,Sayfa2!E:E,A36)+SUMIFS(Sayfa2!J:J,Sayfa2!I:I,A36) -> 12.15 | D36: =C36/C$42*100 -> 28.085992 | E36: =+IF(C36>0.01,1,0) -> 1
A37: Sudak | B37: S. lucioperca | C37: =+SUMIFS(Sayfa2!$B:$B,Sayfa2!A:A,A37)+SUMIFS(Sayfa2!F:F,Sayfa2!E:E,A37)+SUMIFS(Sayfa2!J:J,Sayfa2!I:I,A37) -> 7.53 | D37: =C37/C$42*100 -> 17.40638 | E37: =+IF(C37>0.01,1,0) -> 1
A38: Siraz | B38: Capoeta sp. | C38: =+SUMIFS(Sayfa2!$B:$B,Sayfa2!A:A,A38)+SUMIFS(Sayfa2!F:F,Sayfa2!E:E,A38)+SUMIFS(Sayfa2!J:J,Sayfa2!I:I,A38) -> 0.2 | D38: =C38/C$42*100 -> 0.46232085 | E38: =+IF(C38>0.01,1,0) -> 1
A39: Tatlısu kefali | B39: S.cephalus | C39: =+SUMIFS(Sayfa2!$B:$B,Sayfa2!A:A,A39)+SUMIFS(Sayfa2!F:F,Sayfa2!E:E,A39)+SUMIFS(Sayfa2!J:J,Sayfa2!I:I,A39) -> 0.6 | D39: =C39/C$42*100 -> 1.3869626 | E39: =+IF(C39>0.01,1,0) -> 1
A40: Bıyıklı balık | B40: Barbus sp. | C40: =+SUMIFS(Sayfa2!$B:$B,Sayfa2!A:A,A40)+SUMIFS(Sayfa2!F:F,Sayfa2!E:E,A40)+SUMIFS(Sayfa2!J:J,Sayfa2!I:I,A40) -> 0 | D40: =C40/C$42*100 -> 0 | E40: =+IF(C40>0.01,1,0) -> 0
A41: Kaya balığı | B41: P.marmoratus | C41: =+SUMIFS(Sayfa2!$B:$B,Sayfa2!A:A,A41)+SUMIFS(Sayfa2!F:F,Sayfa2!E:E,A41)+SUMIFS(Sayfa2!J:J,Sayfa2!I:I,A41) -> 0 | D41: =C41/C$42*100 -> 0 | E41: =+IF(C41>0.01,1,0) -> 0
B42: Toplam | C42: =SUM(C35:C41) -> 43.26 | D42: =SUM(D35:D41) -> 100
A46: Rapor örneği
A48: =CONCATENATE(" ",E1," ","avlak sahasında belirlenen"," ","3 istasyonda"," ",G7," ","m²"," ","ağ alanına sahip"," ","ortalama"," ",B10," ","mm"," ","göz açıklığına sahip"," ",A9," ","adet ", "uzatma ağları kullanılarak"," ",Sayfa2!A3," ","-"," ",Sayfa2!A39," ","tarihleri arasında avcılık operasyonları düzenlenmiştir."," ","Denemeler sonucunda"," ",IF(E35=1,A35," "),",",IF(E36=1,A36," ")," ,",IF(E37=1,A37," ")," ",IF(E38=1,A38," "),",",IF(E39=1,A39," "),",",IF(E40=1,A40," "),",",IF(E41=1,A41," ")," ","türlerinden toplam"," ",C42," ","kg"," ","balık yakalanmış olup toplam avın ağırlığına göre dağılımı ise şu şekildedir."," ",IF(E35=1,B35," ")," ","türü"," ","%"," ",ROUND(C35/C$42*100,2),", ",IF(E36=1,B36," ")," ","türü"," ","%"," ",ROUND(C36/C$42*100,2),", ",IF(E37=1,B37," ")," ","türü"," ","%"," ",ROUND(C37/C$42*100,2)," ","vs. Stok büyüklüğünün tahmininde Avşar ve diğ. (2000)’in önerdiği “Uzatma Ağlarıyla Avcılık Yöntemi”nden yararlanılmıştır. Her bir bölge için hesaplanan toplam stok değerleri tabloda görülmektedir."," ","Ayrıca baraj gölündeki avcılık baskısı dikkate alındığında stoktan yararlanma düzeyinin Gulland (1971), E=0,3"," ","olarak alınması uygun bulunmaktadır. Bu durumda yıllık kiralamaya esas stok miktarı"," ",L29," ","ton/yıl olarak tahmin edilmiştir.") -> Saraydüzü Boyabat Baraj Gölü avlak sahasında belirlenen 3 istasyonda 2100 m² ağ alanına sahip ortalama 63 mm göz açıklığına sahip 3 adet uzatma ağları kullanılarak 22.06.2021 - 24.06.2021 tarihleri arasında avcılık operasyonları düzenlenmiştir. Denemeler sonucunda Sazan,Yayın ,Sudak Siraz,Tatlısu kefali, , türlerinden toplam 43,26 kg balık yakalanmış olup toplam avın ağırlığına göre dağılımı ise şu şekildedir. C.carpio türü % 52,66, S. glanis türü % 28,09, S. lucioperca türü % 17,41 vs. Stok büyüklüğünün tahmininde Avşar ve diğ. (2000)’in önerdiği “Uzatma Ağlarıyla Avcılık Yöntemi”nden yararlanılmıştır. Her bir bölge için hesaplanan toplam stok değerleri tabloda görülmektedir. Ayrıca baraj gölündeki avcılık baskısı dikkate alındığında stoktan yararlanma düzeyinin Gulland (1971), E=0,3 olarak alınması uygun bulunmaktadır. Bu durumda yıllık kiralamaya esas stok miktarı 13,8524 ton/yıl olarak tahmin edilmiştir.
A56: NOT: Sonuçta her bir tür için ayrı bir stok hesaplayacaksak eğer her avcılıkta yakaladığımız balıkların ağırlıkça oranlarını tespit etmemiz lazım. Böylece toplamda şu kadar avcılık yaptık şu akdar kilo balık yakaladık bunun %20 si şu türdendi dolayısıyla tespit ettiğimiz stoktaki oranıda budur diyebiliriz.

Sheet Sayfa4
A1: Sazan | B1: =+SUMIFS(Sayfa2!$B$8:$B$17,Sayfa2!$A$8:$A$17,A1) -> 2.53 | C1: =+SUMIFS(Sayfa2!$F$8:$F$17,Sayfa2!$E$8:$E$17,A1) -> 2.38 | D1: =+SUMIFS(Sayfa2!$J$8:$J$17,Sayfa2!$I$8:$I$17,A1) -> 1.28 | E1: =+SUM(B1:D1) -> 6.19
A2: Sudak | B2: =+SUMIFS(Sayfa2!$B$8:$B$17,Sayfa2!$A$8:$A$17,A2) -> 2.52 | C2: =+SUMIFS(Sayfa2!$F$8:$F$17,Sayfa2!$E$8:$E$17,A2) -> 0 | D2: =+SUMIFS(Sayfa2!$J$8:$J$17,Sayfa2!$I$8:$I$17,A2) -> 0 | E2: =+SUM(B2:D2) -> 2.52
A3: Yayın | B3: =+SUMIFS(Sayfa2!$B$8:$B$17,Sayfa2!$A$8:$A$17,A3) -> 1.65 | C3: =+SUMIFS(Sayfa2!$F$8:$F$17,Sayfa2!$E$8:$E$17,A3) -> 0.88 | D3: =+SUMIFS(Sayfa2!$J$8:$J$17,Sayfa2!$I$8:$I$17,A3) -> 0 | E3: =+SUM(B3:D3) -> 2.53
B4: =SUM(B1:B3) -> 6.7 | C4: =SUM(C1:C3) -> 3.26 | D4: =SUM(D1:D3) -> 1.28 | E4: =+SUM(B4:D4) -> 11.24
A6: Sazan | B6: =+SUMIFS(Sayfa2!$B$26:$B$35,Sayfa2!$A$26:$A$35,A6) -> 2.44 | C6: =+SUMIFS(Sayfa2!$F$26:$F$35,Sayfa2!$E$26:$E$35,A6) -> 2.85 | D6: =+SUMIFS(Sayfa2!$J$26:$J$35,Sayfa2!$I$26:$I$35,A6) -> 2.9 | E6: =+SUM(B6:D6) -> 8.19
A7: Sudak | B7: =+SUMIFS(Sayfa2!$B$26:$B$35,Sayfa2!$A$26:$A$35,A7) -> 2.61 | C7: =+SUMIFS(Sayfa2!$F$26:$F$35,Sayfa2!$E$26:$E$35,A7) -> 0 | D7: =+SUMIFS(Sayfa2!$J$26:$J$35,Sayfa2!$I$26:$I$35,A7) -> 0 | E7: =+SUM(B7:D7) -> 2.61
A8: Yayın | B8: =+SUMIFS(Sayfa2!$B$26:$B$35,Sayfa2!$A$26:$A$35,A8) -> 2.7 | C8: =+SUMIFS(Sayfa2!$F$26:$F$35,Sayfa2!$E$26:$E$35,A8) -> 0 | D8: =+SUMIFS(Sayfa2!$J$26:$J$35,Sayfa2!$I$26:$I$35,A8) -> 1.83 | E8: =+SUM(B8:D8) -> 4.53
B9: =SUM(B6:B8) -> 7.75 | C9: =SUM(C6:C8) -> 2.85 | D9: =SUM(D6:D8) -> 4.73 | E9: =+SUM(B9:D9) -> 15.33
A11: Sazan | B11: =+SUMIFS(Sayfa2!$B$44:$B$53,Sayfa2!$A$44:$A$53,A11) -> 2.83 | C11: =+SUMIFS(Sayfa2!$F$44:$F$53,Sayfa2!$E$44:$E$53,A11) -> 2.65 | D11: =+SUMIFS(Sayfa2!$J$44:$J$53,Sayfa2!$I$44:$I$53,A11) -> 2.92 | E11: =+SUM(B11:D11) -> 8.4
A12: Sudak | B12: =+SUMIFS(Sayfa2!$B$44:$B$53,Sayfa2!$A$44:$A$53,A12) -> 0 | C12: =+SUMIFS(Sayfa2!$F$44:$F$53,Sayfa2!$E$44:$E$53,A12) -> 2.4 | D12: =+SUMIFS(Sayfa2!$J$44:$J$53,Sayfa2!$I$44:$I$53,A12) -> 0 | E12: =+SUM(B12:D12) -> 2.4
A13: Yayın | B13: =+SUMIFS(Sayfa2!$B$44:$B$53,Sayfa2!$A$44:$A$53,A13) -> 2.1 | C13: =+SUMIFS(Sayfa2!$F$44:$F$53,Sayfa2!$E$44:$E$53,A13) -> 0 | D13: =+SUMIFS(Sayfa2!$J$44:$J$53,Sayfa2!$I$44:$I$53,A13) -> 2.99 | E13: =+SUM(B13:D13) -> 5.09
B14: =SUM(B11:B13) -> 4.93 | C14: =SUM(C11:C13) -> 5.05 | D14: =SUM(D11:D13) -> 5.91 | E14: =+SUM(B14:D14) -> 15.89
E15: =+E4+E9+E14 -> 42.46
