Workbook

Sheet Sayfa2
A1: 02.12.2021-08.12.2021 DURAĞAN ALTINKAYA BARAJ GÖLÜ STOK TESPİT ÇALIŞMASI SONUÇLARI
A3: 03.12.2021 | B3: 1. İSTASYON | E3: =+A3 -> 03.12.2021 | F3: 2. İSTASYON | I3: =+A3 -> 03.12.2021 | J3: 3. İSTASYON
A4: AV ARACI | B4: Boy (m) | C4: Derinlik (m) | D4: Göz Aç.(mm) | E4: AV ARACI | F4: Boy (m) | G4: Derinlik (m) | H4: Göz Aç.(mm) | I4: AV ARACI | J4: Boy (m) | K4: Derinlik (m) | L4: Göz Aç.(mm)
B5: 200 | C5: 10 | D5: 70 | F5: 200 | G5: 5 | H5: 70 | J5: 150 | K5: 5 | L5: 70
A6: KOORDİNAT | B6: 41°17'08.9"N 35°11'38.3"E | E6: KOORDİNAT | F6: 41°16'47.3"N 35°11'32.3"E | I6: KOORDİNAT | J6: 41°16'27.9"N 35°11'43.1"E
A7: TÜRLER | B7: Ağırlık (kg) | D7: Boy (cm) | E7: TÜRLER | F7: Ağırlık (kg) | H7: Boy (cm) | I7: TÜRLER | J7: Ağırlık (kg) | L7: Boy (cm)
A8: Gümişi Balık | B8: 0.62 | D8: 33 | E8: Gümişi Balık | F8: 0.46 | H8: 28 | I8: Gümişi Balık | J8: 0.93 | L8: 40
A9: Siraz | B9: 0.23 | D9: 26 | E9: Sudak | F9: 2.1 | H9: 60 | I9: Gümişi Balık | J9: 0.74 | L9: 35
A10: Siraz | B10: 0.21 | D10: 24 | E10: Sazan | F10: 0.95 | H10: 38 | I10: Sazan | J10: 1.28 | L10: 46
A11: Sazan | B11: 1.25 | D11: 48 | E11: Sazan | F11: 1.25 | H11: 43 | I11: Gümişi Balık | J11: 0.59 | L11: 32
A12: Gümişi Balık | B12: 0.56 | D12: 30 | E12: Sazan | F12: 1.28 | H12: 45 | I12: Bıyıklı Balık | J12: 0.56 | L12: 31
A13: Tatlısu kefali | B13: 0.58 | D13: 29 | E13: Siraz | F13: 0.26 | H13: 31 | I13: Siraz | J13: 0.21 | L13: 24
A14: Siraz | B14: 0.22 | D14: 26 | E14: Siraz | F14: 0.24 | H14: 25 | I14: Siraz | J14: 0.23 | L14: 27
A15: Siraz | B15: 0.24 | D15: 23 | E15: Siraz | F15: 0.24 | H15: 23 | I15: Siraz | J15: 0.22 | L15: 25
A16: Gümişi Balık | B16: 0.61 | D16: 32 | E16: Gümişi Balık | F16: 0.62 | H16: 33 | I16: Gümişi Balık | J16: 0.6 | L16: 31
A18: Toplam | B18: =SUM(B8:C17) -> 4.52 | E18: Toplam | F18: =SUM(F8:G17) -> 7.4 | I18: Toplam | J18: =SUM(J8:K17) -> 5.36
A19: =+B18+F18+J18 -> 17.28
A21: 07.12.2021 | B21: 1. İSTASYON | E21: =+A21 -> 07.12.2021 | F21: 2. İSTASYON | I21: =+A21 -> 07.12.2021 | J21: 3. İSTASYON
A22: AV ARACI | B22: Boy (m) | C22: Derinlik (m) | D22: Göz Aç.(mm) | E22: AV ARACI | F22: Boy (m) | G22: Derinlik (m) | H22: Göz Aç.(mm) | I22: AV ARACI | J22: Boy (m) | K22: Derinlik (m) | L22: Göz Aç.(mm)
B23: =+B5 -> 200 | C23: =+C5 -> 10 | D23: =+D5 -> 70 | F23: =+F5 -> 200 | G23: =+G5 -> 5 | H23: =+H5 -> 70 | J23: =+J5 -> 150 | K23: =+K5 -> 5 | L23: =+L5 -> 70
A24: KOORDİNAT | B24: =+B6 -> 41°17'08.9"N 35°11'38.3"E | E24: KOORDİNAT | F24: =+F6 -> 41°16'47.3"N 35°11'32.3"E | I24: KOORDİNAT | J24: =+J6 -> 41°16'27.9"N 35°11'43.1"E
A25: TÜRLER | B25: Ağırlık (kg) | D25: Boy (cm) | E25: TÜRLER | F25: Ağırlık (kg) | H25: Boy (cm) | I25: TÜRLER | J25: Ağırlık (kg) | L25: Boy (cm)
A26: Tatlısu kefali | B26: 0.63 | D26: 31 | E26: Gümişi Balık | F26: 0.43 | H26: 30 | I26: Gümişi Balık | J26: 0.46 | L26: 30
A27: Sazan | B27: 1.42 | D27: 48 | E27: Sazan | F27: 1.79 | H27: 51 | I27: Sazan | J27: 1.31 | L27: 46
A28: Siraz | B28: 0.2 | D28: 22 | E28: Tatlısu kefali | F28: 0.6 | H28: 30 | I28: Siraz | J28: 0.24 | L28: 24
A29: Siraz | B29: 0.22 | D29: 23 | E29: Siraz | F29: 0.24 | H29: 23 | I29: Siraz | J29: 0.23 | L29: 23
A30: Gümişi Balık | B30: 0.27 | D30: 26 | E30: Siraz | F30: 0.21 | H30: 21 | I30: Bıyıklı Balık | J30: 0.53 | L30: 29
A31: Siraz | B31: 0.24 | D31: 23 | E31: Siraz | F31: 0.24 | H31: 23 | I31: Sudak | J31: 2.05 | L31: 58
A32: Siraz | B32: 0.24 | D32: 23 | E32: Siraz | F32: 0.24 | H32: 23 | I32: Siraz | J32: 0.24 | L32: 23
E33: Gümişi Balık | F33: 0.6 | H33: 31 | I33: Gümişi Balık | J33: 0.61 | L33: 32
A34: Sazan | B34: 1.366 | D34: 45 | E34: Sazan | F34: 0.95 | H34: 38 | I34: Sazan | J34: 1.42 | L34: 48
A36: Toplam | B36: =+SUM(B26:B35) -> 4.586 | E36: Toplam | F36: =SUM(F26:G35) -> 5.3 | I36: Toplam | J36: =SUM(J26:K35) -> 7.09
A37: =+B36+F36+J36 -> 16.976
A39: 08.12.2021 | B39: 1. İSTASYON | E39: =+A39 -> 08.12.2021 | F39: 2. İSTASYON | I39: =+A39 -> 08.12.2021 | J39: 3. İSTASYON
A40: AV ARACI | B40: Boy (m) | C40: Derinlik (m) | D40: Göz Aç.(mm) | E40: AV ARACI | F40: Boy (m) | G40: Derinlik (m) | H40: Göz Aç.(mm) | I40: AV ARACI | J40: Boy (m) | K40: Derinlik (m) | L40: Göz Aç.(mm)
B41: =+B23 -> 200 | C41: =+C23 -> 10 | D41: =+D23 -> 70 | F41: =+F23 -> 200 | G41: =+G23 -> 5 | H41: =+H23 -> 70 | J41: =+J23 -> 150 | K41: =+K23 -> 5 | L41: =+L23 -> 70
A42: KOORDİNAT | B42: =+B24 -> 41°17'08.9"N 35°11'38.3"E | E42: KOORDİNAT | F42: =+F24 -> 41°16'47.3"N 35°11'32.3"E | I42: KOORDİNAT | J42: =+J24 -> 41°16'27.9"N 35°11'43.1"E
A43: TÜRLER | B43: Ağırlık (kg) | D43: Boy (cm) | E43: TÜRLER | F43: Ağırlık (kg) | H43: Boy (cm) | I43: TÜRLER | J43: Ağırlık (kg) | L43: Boy (cm)
A44: Gümişi Balık | B44: 0.62 | D44: 33 | E44: Gümişi Balık | F44: 0.74 | H44: 35 | I44: Sazan | J44: 1.25 | L44: 43
A45: Sazan | B45: 1.31 | D45: 47 | E45: Sazan | F45: 1.31 | H45: 47 | I45: Siraz | J45: 0.23 | L45: 22
...

Sheet Sonuç
B1: İstasyonların alanları (km2) | E1: DURAĞAN ALTINKAYA BARAJ GÖLÜ | H1: =+I1/1000000 -> 23 | I1: =+C2+C3+C4 -> 23000000
A2: 1. İst | B2: 8 | C2: =+B2*1000000 -> 8000000 | E2: Balıkçı Sayısı | H2: 150
A3: 2. ist | B3: 8 | C3: =+B3*1000000 -> 8000000 | E3: Ticari Türler | H3: =+CONCATENATE(B35,", ",B36,", ",B37,", ",B38,", ",B39,", ",B40,", ",B41," ","vs.") -> C.carpio, S. glanis, S. lucioperca, Capoeta sp., S.cephalus, Barbus sp., C.gibelio vs.
A4: 3. ist | B4: 7 | C4: =+B4*1000000 -> 7000000
A6: Ağlar | B6: Ağ göz açıklığı (mm) | C6: Ağ uzunluğu (m) | D6: Derinlik Göz Sayısı (adet) | E6: Ağın Derinliği (m) | F6: Ağın Alanı (m2) | G6: Tüm Ağların Alanı (m2)
A7: 1 | B7: =+Sayfa2!D5 -> 70 | C7: =+Sayfa2!B5 -> 200 | E7: =+Sayfa2!C5 -> 10 | F7: =C7*E7 -> 2000 | G7: =SUM(F7:F9) -> 3750
A8: 2 | B8: =+Sayfa2!H5 -> 70 | C8: =+Sayfa2!F5 -> 200 | E8: =+Sayfa2!G5 -> 5 | F8: =C8*E8 -> 1000
A9: 3 | B9: =+Sayfa2!L5 -> 70 | C9: =+Sayfa2!J5 -> 150 | E9: =+Sayfa2!K5 -> 5 | F9: =C9*E9 -> 750
B10: =+ROUND(AVERAGE(B7:B9),0) -> 70
D11: Avlanan Miktarlar (kg) | G11: Birim alandaki stok yoğunluğu (kg/m2) | J11: Toplam Stok (kg)
A12: Avcılık No: | B12: Avcılık Tarihi | C12: Ağların alanı (m2) | D12: 1. İst. | E12: 2. ist. | F12: 3. ist. | G12: 1. İst. | H12: 2. ist. | I12: 3. ist. | J12: 1. İst. | K12: 2. ist. | L12: 3. ist.
B13: =+Sayfa2!A3 -> 03.12.2021 | C13: =G7 -> 3750 | D13: =+Sayfa2!B18 -> 4.52 | E13: =+Sayfa2!F18 -> 7.4 | F13: =+Sayfa2!J18 -> 5.36 | G13: =D13/$C$13 -> 0.0012053333 | H13: =E13/$C$13 -> 0.0019733333 | I13: =F13/$C$13 -> 0.0014293333 | J13: =G13*$C$2 -> 9642.6667 | K13: =H13*$C$3 -> 15786.667 | L13: =I13*$C$4 -> 10005.333
B14: =+Sayfa2!A21 -> 07.12.2021 | D14: =+Sayfa2!B36 -> 4.586 | E14: =+Sayfa2!F36 -> 5.3 | F14: =+Sayfa2!J36 -> 7.09 | G14: =D14/$C$13 -> 0.0012229333 | H14: =E14/$C$13 -> 0.0014133333 | I14: =F14/$C$13 -> 0.0018906667 | J14: =G14*$C$2 -> 9783.4667 | K14: =H14*$C$3 -> 11306.667 | L14: =I14*$C$4 -> 13234.667
B15: =+Sayfa2!A39 -> 08.12.2021 | D15: =+Sayfa2!B54 -> 4.91 | E15: =+Sayfa2!F54 -> 3 | F15: =+Sayfa2!J54 -> 2.44 | G15: =D15/$C$13 -> 0.0013093333 | H15: =E15/$C$13 -> 0.0008 | I15: =F15/$C$13 -> 0.00065066667 | J15: =G15*$C$2 -> 10474.667 | K15: =H15*$C$3 -> 6400 | L15: =I15*$C$4 -> 4554.6667
G16: =D16/$C$13 -> 0 | H16: =E16/$C$13 -> 0 | I16: =F16/$C$13 -> 0 | J16: =G16*$C$2 -> 0 | K16: =H16*$C$3 -> 0 | L16: =I16*$C$4 -> 0
G17: =D17/$C$13 -> 0 | H17: =E17/$C$13 -> 0 | I17: =F17/$C$13 -> 0 | J17: =G17*$C$2 -> 0 | K17: =H17*$C$3 -> 0 | L17: =I17*$C$4 -> 0
G18: =D18/$C$13 -> 0 | H18: =E18/$C$13 -> 0 | I18: =F18/$C$13 -> 0 | J18: =G18*$C$2 -> 0 | K18: =H18*$C$3 -> 0 | L18: =I18*$C$4 -> 0
G19: =D19/$C$13 -> 0 | H19: =E19/$C$13 -> 0 | I19: =F19/$C$13 -> 0 | J19: =G19*$C$2 -> 0 | K19: =H19*$C$3 -> 0 | L19: =I19*$C$4 -> 0
G20: =D20/$C$13 -> 0 | H20: =E20/$C$13 -> 0 | I20: =F20/$C$13 -> 0 | J20: =G20*$C$2 -> 0 | K20: =H20*$C$3 -> 0 | L20: =I20*$C$4 -> 0
G21: =D21/$C$13 -> 0 | H21: =E21/$C$13 -> 0 | I21: =F21/$C$13 -> 0 | J21: =G21*$C$2 -> 0 | K21: =H21*$C$3 -> 0 | L21: =I21*$C$4 -> 0
G22: =D22/$C$13 -> 0 | H22: =E22/$C$13 -> 0 | I22: =F22/$C$13 -> 0 | J22: =G22*$C$2 -> 0 | K22: =H22*$C$3 -> 0 | L22: =I22*$C$4 -> 0
A23: Ortalama (kg) | D23: =AVERAGE(D13:D22) -> 4.672 | E23: =AVERAGE(E13:E22) -> 5.2333333 | F23: =AVERAGE(F13:F22) -> 4.9633333 | G23: =D23/$C$13 -> 0.0012458667 | H23: =E23/$C$13 -> 0.0013955556 | I23: =F23/$C$13 -> 0.0013235556 | J23: =G23*$C$2 -> 9966.9333 | K23: =H23*$C$3 -> 11164.444 | L23: =I23*$C$4 -> 9264.8889
A24: Toplam Biyomas (ton) | J24: =SUM(J23:L23)/1000 -> 30.396267
B27: 0,5 donam faktörüyle donanmış bir ağın derinliğini hesaplamak için kullanılan sabit katsayı | F27: E= 0,3 ile 0,6 arasında tercih edilebilir, ideal değeri 0,5 olarak kabul edilir
F28: E=0,5 | G28: alınırsa | H28: Avlanabilir Stok (kiralamaya esas) = | K28: =J24*0.5 -> 15.198133 | L28: =+ROUND(K28,3) -> 15.198
F29: E=0,3 | G29: alınırsa | H29: Avlanabilir Stok (kiralamaya esas) = | K29: =J24*0.3 -> 9.11888 | L29: =+ROUND(K29,3) -> 9.119
F30: E=0,4 | G30: alınırsa | H30: Avlanabilir Stok (kiralamaya esas) = | K30: =J24*0.4 -> 12.158507 | L30: =+ROUND(K30,3) -> 12.159
C33: Avlanan Miktarlar (kg) | D33: Türlerin toplam avdaki oranları
A35: Sazan | B35: C.carpio | C35: =+SUMIFS(Sayfa2!$B:$B,Sayfa2!A:A,A35)+SUMIFS(Sayfa2!F:F,Sayfa2!E:E,A35)+SUMIFS(Sayfa2!J:J,Sayfa2!I:I,A35) -> 18.136 | D35: =C35/C$42*100 -> 40.658207 | E35: =+IF(C35>0.01,1,0) -> 1
A36: Yayın | B36: S. glanis | C36: =+SUMIFS(Sayfa2!$B:$B,Sayfa2!A:A,A36)+SUMIFS(Sayfa2!F:F,Sayfa2!E:E,A36)+SUMIFS(Sayfa2!J:J,Sayfa2!I:I,A36) -> 1.85 | D36: =C36/C$42*100 -> 4.1474241 | E36: =+IF(C36>0.01,1,0) -> 1
A37: Sudak | B37: S. lucioperca | C37: =+SUMIFS(Sayfa2!$B:$B,Sayfa2!A:A,A37)+SUMIFS(Sayfa2!F:F,Sayfa2!E:E,A37)+SUMIFS(Sayfa2!J:J,Sayfa2!I:I,A37) -> 4.15 | D37: =C37/C$42*100 -> 9.3036811 | E37: =+IF(C37>0.01,1,0) -> 1
A38: Siraz | B38: Capoeta sp. | C38: =+SUMIFS(Sayfa2!$B:$B,Sayfa2!A:A,A38)+SUMIFS(Sayfa2!F:F,Sayfa2!E:E,A38)+SUMIFS(Sayfa2!J:J,Sayfa2!I:I,A38) -> 6.24 | D38: =C38/C$42*100 -> 13.989149 | E38: =+IF(C38>0.01,1,0) -> 1
A39: Tatlısu kefali | B39: S.cephalus | C39: =+SUMIFS(Sayfa2!$B:$B,Sayfa2!A:A,A39)+SUMIFS(Sayfa2!F:F,Sayfa2!E:E,A39)+SUMIFS(Sayfa2!J:J,Sayfa2!I:I,A39) -> 3.19 | D39: =C39/C$42*100 -> 7.1515043 | E39: =+IF(C39>0.01,1,0) -> 1
A40: Bıyıklı balık | B40: Barbus sp. | C40: =+SUMIFS(Sayfa2!$B:$B,Sayfa2!A:A,A40)+SUMIFS(Sayfa2!F:F,Sayfa2!E:E,A40)+SUMIFS(Sayfa2!J:J,Sayfa2!I:I,A40) -> 1.58 | D40: =C40/C$42*100 -> 3.5421244 | E40: =+IF(C40>0.01,1,0) -> 1
A41: Gümişi Balık | B41: C.gibelio | C41: =+SUMIFS(Sayfa2!$B:$B,Sayfa2!A:A,A41)+SUMIFS(Sayfa2!F:F,Sayfa2!E:E,A41)+SUMIFS(Sayfa2!J:J,Sayfa2!I:I,A41) -> 9.46 | D41: =C41/C$42*100 -> 21.207909 | E41: =+IF(C41>0.01,1,0) -> 1
B42: Toplam | C42: =SUM(C35:C41) -> 44.606 | D42: =SUM(D35:D41) -> 100
A46: Rapor örneği
A48: =CONCATENATE(" ",E1," ","avlak sahasında belirlenen"," ","3 istasyonda"," ",G7," ","m²"," ","ağ alanına sahip"," ","ortalama"," ",B10," ","mm"," ","göz açıklığına sahip"," ",A9," ","adet ", "uzatma ağları kullanılarak"," ",Sayfa2!A3," ","-"," ",Sayfa2!A39," ","tarihleri arasında avcılık operasyonları düzenlenmiştir."," ","Denemeler sonucunda"," ",IF(E35=1,A35," "),", ",IF(E36=1,A36," "),", ",IF(E37=1,A37," "),", ",IF(E38=1,A38," "),", ",IF(E39=1,A39," "),", ",IF(E40=1,A40," "),", ",IF(E41=1,A41," ")," ","türlerinden toplam"," ",C42," ","kg"," ","balık yakalanmış olup toplam avın ağırlığına göre dağılımı ise şu şekildedir."," ",IF(E35=1,B35," ")," ","türü"," ","%"," ",ROUND(C35/C$42*100,2),", ",IF(E36=1,B36," ")," ","türü"," ","%"," ",ROUND(C36/C$42*100,2),", ",IF(E37=1,B37," ")," ","türü"," ","%"," ",ROUND(C37/C$42*100,2),", ",IF(E38=1,B38," ")," ","türü"," ","%"," ",ROUND(C38/C$42*100,2),", ",IF(E39=1,B39," ")," ","türü"," ","%"," ",ROUND(C39/C$42*100,2),", ",IF(E40=1,B40," ")," ","türü"," ","%"," ",ROUND(C40/C$42*100,2),", ",IF(E41=1,B41," ")," ","türü"," ","%"," ",ROUND(C41/C$42*100,2),". ","Stok büyüklüğünün tahmininde Avşar ve diğ. (2000)’in önerdiği “Uzatma Ağlarıyla Avcılık Yöntemi”nden yararlanılmıştır. Her bir bölge için hesaplanan toplam stok değerleri tabloda görülmektedir."," ","Ayrıca baraj gölündeki avcılık baskısı dikkate alındığında stoktan yararlanma düzeyinin Gulland (1971), E=0,3"," ","olarak alınması uygun bulunmaktadır. Bu durumda yıllık kiralamaya esas stok miktarı"," ",L29," ","ton/yıl olarak tahmin edilmiştir.") -> DURAĞAN ALTINKAYA BARAJ GÖLÜ avlak sahasında belirlenen 3 istasyonda 3750 m² ağ alanına sahip ortalama 70 mm göz açıklığına sahip 3 adet uzatma ağları kullanılarak 03.12.2021 - 08.12.2021 tarihleri arasında avcılık operasyonları düzenlenmiştir. Denemeler sonucunda Sazan, Yayın, Sudak, Siraz, Tatlısu kefali, Bıyıklı balık, Gümişi Balık türlerinden toplam 44,606 kg balık yakalanmış olup toplam avın ağırlığına göre dağılımı ise şu şekildedir. C.carpio türü % 40,66, S. glanis türü % 4,15, S. lucioperca türü % 9,3, Capoeta sp. türü % 13,99, S.cephalus türü % 7,15, Barbus sp. türü % 3,54, C.gibelio türü % 21,21. Stok büyüklüğünün tahmininde Avşar ve diğ. (2000)’in önerdiği “Uzatma Ağlarıyla Avcılık Yöntemi”nden yararlanılmıştır. Her bir bölge için hesaplanan toplam stok değerleri tabloda görülmektedir. Ayrıca baraj gölündeki avcılık baskısı dikkate alındığında stoktan yararlanma düzeyinin Gulland (1971), E=0,3 olarak alınması uygun bulunmaktadır. Bu durumda yıllık kiralamaya esas stok miktarı 9,119 ton/yıl olarak tahmin edilmiştir.
A50: NOT: Sonuçta her bir tür için ayrı bir stok hesaplayacaksak eğer her avcılıkta yakaladığımız balıkların ağırlıkça oranlarını tespit etmemiz lazım. Böylece toplamda şu kadar avcılık yaptık şu akdar kilo balık yakaladık bunun %20 si şu türdendi dolayısıyla tespit ettiğimiz stoktaki oranıda budur diyebiliriz.

Sheet Sayfa4
A1: 1- Gelirler | I1: =+Sonuç!A35 -> Sazan | J1: =+Sonuç!B35 -> C.carpio | K1: =+Sonuç!$K$29*Sonuç!D35*10 -> 3707.5731
A2: Tür / Latince Adı | B2: Stok Mik.(Kg) | C2: Birim Fiyatı (TL/Kg) | D2: Tutarı (TL) | I2: =+Sonuç!A36 -> Yayın | J2: =+Sonuç!B36 -> S. glanis | K2: =+Sonuç!$K$29*Sonuç!D36*10 -> 378.19863
A3: =+CONCATENATE(I1," ","( ",J1," )") -> Sazan ( C.carpio ) | B3: =+ROUND(K1,0) -> 3708 | C3: 16 | D3: =+B3*C3 -> 59328 | I3: =+Sonuç!A37 -> Sudak | J3: =+Sonuç!B37 -> S. lucioperca | K3: =+Sonuç!$K$29*Sonuç!D37*10 -> 848.39152
A4: =+CONCATENATE(I2," ","( ",J2," )") -> Yayın ( S. glanis ) | B4: =+ROUND(K2,0) -> 378 | C4: 21 | D4: =+B4*C4 -> 7938 | I4: =+Sonuç!A38 -> Siraz | J4: =+Sonuç!B38 -> Capoeta sp. | K4: =+Sonuç!$K$29*Sonuç!D38*10 -> 1275.6538
A5: =+CONCATENATE(I3," ","( ",J3," )") -> Sudak ( S. lucioperca ) | B5: =+ROUND(K3,0) -> 848 | C5: 23 | D5: =+B5*C5 -> 19504 | I5: =+Sonuç!A39 -> Tatlısu kefali | J5: =+Sonuç!B39 -> S.cephalus | K5: =+Sonuç!$K$29*Sonuç!D39*10 -> 652.13709
A6: =+CONCATENATE(I4," ","( ",J4," )") -> Siraz ( Capoeta sp. ) | B6: =+ROUND(K4,0) -> 1276 | C6: 10 | D6: =+B6*C6 -> 12760 | I6: =+Sonuç!A40 -> Bıyıklı balık | J6: =+Sonuç!B40 -> Barbus sp. | K6: =+Sonuç!$K$29*Sonuç!D40*10 -> 323.00207
A7: =+CONCATENATE(I5," ","( ",J5," )") -> Tatlısu kefali ( S.cephalus ) | B7: =+ROUND(K5,0) -> 652 | C7: 20 | D7: =+B7*C7 -> 13040 | I7: =+Sonuç!A41 -> Gümişi Balık | J7: =+Sonuç!B41 -> C.gibelio | K7: =+Sonuç!$K$29*Sonuç!D41*10 -> 1933.9238
A8: =+CONCATENATE(I6," ","( ",J6," )") -> Bıyıklı balık ( Barbus sp. ) | B8: =+ROUND(K6,0) -> 323 | C8: 7 | D8: =+B8*C8 -> 2261 | K8: =SUM(K1:K7) -> 9118.88
A9: =+CONCATENATE(I7," ","( ",J7," )") -> Gümişi Balık ( C.gibelio ) | B9: =+ROUND(K7,0) -> 1934 | C9: 7 | D9: =+B9*C9 -> 13538
A10: Toplam | B10: =SUM(B3:B9) -> 9119 | D10: =SUM(D3:D9) -> 128369
A11: 2- Yatırm Giderleri
A12: Yatırımın Cinsi | B12: Miktarı (Ad) | C12: Birim Fiyatı (TL/Kg) | D12: Tutarı (TL)
A13: Motorlu Tekne | B13: 3 | C13: 25000 | D13: =+B13*C13 -> 75000
A14: Motorsuz Tekne
A15: Pinter-Sepet
A16: Ağ (Takım) | B16: 6 | C16: 2250 | D16: =+B16*C16 -> 13500
A17: Diğer | D17: =+B17*C17 -> 0
A18: Toplam | D18: =SUM(D13:D17) -> 88500
A19: 3-İşletme Giderleri
A20: a) Personel Giderleri
A21: Personel | B21: Adedi | C21: Çalıştığı Süre (Ay) | D21: Aylığı (TL) | E21: Tutarı (TL)
A22: Balıkçı | B22: =+B13*2 -> 6 | C22: 4 | D22: 2825 | E22: =+B22*C22*D22 -> 67800
A23: İşçi
A24: Diğer
A25: Toplam | B25: =SUM(B22:B24) -> 6 | E25: =SUM(E22:E24) -> 67800
A26: b) Akaryakıt Giderleri
A27: Yıllık Avlanma Günü | B27: Tekne Sayısı | C27: Günde Harcanan Yakıt (Lt) | D27: Yakıt Litre Fiyatı (TL) | E27: Tutarı (TL)
A28: =+C22*30*2 -> 240 | B28: =+B13 -> 3 | C28: 3 | D28: 9.7 | E28: =+A28*B28*C28*D28 -> 20952
A29: c) Pazarlama Giderleri
A30: Toplam Gelirler | B30: Gider Oranı (%) | D30: Tutar (TL)
A31: =+D10 -> 128369 | B31: 0.03 | D31: =+A31*B31 -> 3851.07
A32: d) Amortisman Giderleri
A33: Yatırımın Cinsi | B33: Miktarı (Ad) | C33: Kullanım Ömrü | D33: Tutarı (TL)
A34: Motorlu Tekne | B34: =+B13*C13 -> 75000 | C34: 25000 | D34: =+B34/C34*1000 -> 3000
A35: Motorsuz Tekne
A36: Pinter-Sepet
A37: Ağ (Takım) | B37: =+B16*C16 -> 13500 | C37: 2 | D37: =+B37/C37 -> 6750
A38: Diğer
A39: Toplam | B39: =SUM(B34:B38) -> 88500 | D39: =SUM(D34:D38) -> 9750
A40: e) Beklenmeyen Giderler
...
