Workbook

Sheet Sayfa2
A1: 02.12.2021-08.12.2021 DURAĞAN ALTINKAYA BARAJ GÖLÜ STOK TESPİT ÇALIŞMASI SONUÇLARI
A3: 03.12.2021 | B3: 1. İSTASYON | E3: =+A3 -> 03.12.2021 | F3: 2. İSTASYON | I3: =+A3 -> 03.12.2021 | J3: 3. İSTASYON
A4: AV ARACI | B4: Boy (m) | C4: Derinlik (m) | D4: Göz Aç.(mm) | E4: AV ARACI | F4: Boy (m) | G4: Derinlik (m) | H4: Göz Aç.(mm) | I4: AV ARACI | J4: Boy (m) | K4: Derinlik (m) | L4: Göz Aç.(mm)
B5: 200 | C5: 10 | D5: 70 | F5: 200 | G5: 5 | H5: 70 | J5: 150 | K5: 5 | L5: 70
A6: KOORDİNAT | B6: 41°17'08.9"N 35°11'38.3"E | E6: KOORDİNAT | F6: 41°16'47.3"N 35°11'32.3"E | I6: KOORDİNAT | J6: 41°16'27.9"N 35°11'43.1"E
A7: TÜRLER | B7: Ağırlık (kg) | D7: Boy (cm) | E7: TÜRLER | F7: Ağırlık (kg) | H7: Boy (cm) | I7: TÜRLER | J7: Ağırlık (kg) | L7: Boy (cm)
A8: Gümişi Balık | B8: 0.62 | D8: 33 | E8: Gümişi Balık | F8: 0.46 | H8: 28 | I8: Gümişi Balık | J8: 0.93 | L8: 40
A9: Siraz | B9: 0.23 | D9: 26 | E9: Sudak | F9: 2.1 | H9: 60 | I9: Gümişi Balık | J9: 0.74 | L9: 35
A10: Siraz | B10: 0.21 | D10: 24 | E10: Sazan | F10: 0.95 | H10: 38 | I10: Sazan | J10: 1.28 | L10: 46
A11: Sazan | B11: 1.25 | D11: 48 | E11: Sazan | F11: 1.25 | H11: 43 | I11: Gümişi Balık | J11: 0.59 | L11: 32
A12: Gümişi Balık | B12: 0.56 | D12: 30 | E12: Sazan | F12: 1.28 | H12: 45 | I12: Bıyıklı Balık | J12: 0.56 | L12: 31
A13: Tatlısu kefali | B13: 0.58 | D13: 29 | E13: Siraz | F13: 0.26 | H13: 31 | I13: Siraz | J13: 0.21 | L13: 24
A14: Siraz | B14: 0.22 | D14: 26 | E14: Siraz | F14: 0.24 | H14: 25 | I14: Siraz | J14: 0.23 | L14: 27
A15: Siraz | B15: 0.24 | D15: 23 | E15: Siraz | F15: 0.24 | H15: 23 | I15: Siraz | J15: 0.22 | L15: 25
A16: Gümişi Balık | B16: 0.61 | D16: 32 | E16: Gümişi Balık | F16: 0.62 | H16: 33 | I16: Gümişi Balık | J16: 0.6 | L16: 31
A18: Toplam | B18: =SUM(B8:C17) -> 4.52 | E18: Toplam | F18: =SUM(F8:G17) -> 7.4 | I18: Toplam | J18: =SUM(J8:K17) -> 5.36
A19: =+B18+F18+J18 -> 17.28
A21: 07.12.2021 | B21: 1. İSTASYON | E21: =+A21 -> 07.12.2021 | F21: 2. İSTASYON | I21: =+A21 -> 07.12.2021 | J21: 3. İSTASYON
A22: AV ARACI | B22: Boy (m) | C22: Derinlik (m) | D22: Göz Aç.(mm) | E22: AV ARACI | F22: Boy (m) | G22: Derinlik (m) | H22: Göz Aç.(mm) | I22: AV ARACI | J22: Boy (m) | K22: Derinlik (m) | L22: Göz Aç.(mm)
B23: =+B5 -> 200 | C23: =+C5 -> 10 | D23: =+D5 -> 70 | F23: =+F5 -> 200 | G23: =+G5 -> 5 | H23: =+H5 -> 70 | J23: =+J5 -> 150 | K23: =+K5 -> 5 | L23: =+L5 -> 70
A24: KOORDİNAT | B24: =+B6 -> 41°17'08.9"N 35°11'38.3"E | E24: KOORDİNAT | F24: =+F6 -> 41°16'47.3"N 35°11'32.3"E | I24: KOORDİNAT | J24: =+J6 -> 41°16'27.9"N 35°11'43.1"E
A25: TÜRLER | B25: Ağırlık (kg) | D25: Boy (cm) | E25: TÜRLER | F25: Ağırlık (kg) | H25: Boy (cm) | I25: TÜRLER | J25: Ağırlık (kg) | L25: Boy (cm)
A26: Tatlısu kefali | B26: 0.63 | D26: 31 | E26: Gümişi Balık | F26: 0.43 | H26: 30 | I26: Gümişi Balık | J26: 0.46 | L26: 30
A27: Sazan | B27: 1.42 | D27: 48 | E27: Sazan | F27: 1.79 | H27: 51 | I27: Sazan | J27: 1.31 | L27: 46
A28: Siraz | B28: 0.2 | D28: 22 | E28: Tatlısu kefali | F28: 0.6 | H28: 30 | I28: Siraz | J28: 0.24 | L28: 24
A29: Siraz | B29: 0.22 | D29: 23 | E29: Siraz | F29: 0.24 | H29: 23 | I29: Siraz | J29: 0.23 | L29: 23
A30: Gümişi Balık | B30: 0.27 | D30: 26 | E30: Siraz | F30: 0.21 | H30: 21 | I30: Bıyıklı Balık | J30: 0.53 | L30: 29
A31: Siraz | B31: 0.24 | D31: 23 | E31: Siraz | F31: 0.24 | H31: 23 | I31: Sudak | J31: 2.05 | L31: 58
A32: Siraz | B32: 0.24 | D32: 23 | E32: Siraz | F32: 0.24 | H32: 23 | I32: Siraz | J32: 0.24 | L32: 23
A33: Sazan | B33: 1.366 | D33: 45 | E33: Gümişi Balık | F33: 0.6 | H33: 31 | I33: Gümişi Balık | J33: 0.61 | L33: 32
E34: Sazan | F34: 0.95 | H34: 38 | I34: Sazan | J34: 1.42 | L34: 48
A36: Toplam | B36: =+SUM(B26:B35) -> 4.586 | E36: Toplam | F36: =SUM(F26:G35) -> 5.3 | I36: Toplam | J36: =SUM(J26:K35) -> 7.09
A37: =+B36+F36+J36 -> 16.976
A39: 08.12.2021 | B39: 1. İSTASYON | E39: =+A39 -> 08.12.2021 | F39: 2. İSTASYON | I39: =+A39 -> 08.12.2021 | J39: 3. İSTASYON
A40: AV ARACI | B40: Boy (m) | C40: Derinlik (m) | D40: Göz Aç.(mm) | E40: AV ARACI | F40: Boy (m) | G40: Derinlik (m) | H40: Göz Aç.(mm) | I40: AV ARACI | J40: Boy (m) | K40: Derinlik (m) | L40: Göz Aç.(mm)
B41: =+B23 -> 200 | C41: =+C23 -> 10 | D41: =+D23 -> 70 | F41: =+F23 -> 200 | G41: =+G23 -> 5 | H41: =+H23 -> 70 | J41: =+J23 -> 150 | K41: =+K23 -> 5 | L41: =+L23 -> 70
A42: KOORDİNAT | B42: =+B24 -> 41°17'08.9"N 35°11'38.3"E | E42: KOORDİNAT | F42: =+F24 -> 41°16'47.3"N 35°11'32.3"E | I42: KOORDİNAT | J42: =+J24 -> 41°16'27.9"N 35°11'43.1"E
A43: TÜRLER | B43: Ağırlık (kg) | D43: Boy (cm) | E43: TÜRLER | F43: Ağırlık (kg) | H43: Boy (cm) | I43: TÜRLER | J43: Ağırlık (kg) | L43: Boy (cm)
A44: Gümişi Balık | B44: 0.62 | D44: 33 | E44: Gümişi Balık | F44: 0.74 | H44: 35 | I44: Sazan | J44: 1.25 | L44: 43
A45: Sazan | B45: 1.31 | D45: 47 | E45: Sazan | F45: 1.31 | H45: 47 | I45: Siraz | J45: 0.23 | L45: 22
...

Sheet Sonuç
B1: İstasyonların alanları (km2) | E1: Altınkaya Baraj Gölü | H1: 23 | I1: =+C2+C3+C4 -> 23000000
A2: 1. İst | B2: =+$H$1/3 -> 7.6666667 | C2: =+B2*1000000 -> 7666666.7 | E2: Balıkçı Sayısı | H2: 200
A3: 2. ist | B3: =+$H$1/3 -> 7.6666667 | C3: =+B3*1000000 -> 7666666.7 | E3: Ticari Türler | H3: =+CONCATENATE(B35,",",B36,",",B37,",",B38,",",B39,",",B40," ,",B41," ","vs.") -> C.carpio,S. glanis,S. lucioperca,Capoeta sp.,S.cephalus,Barbus sp. ,P.marmoratus vs.
A4: 3. ist | B4: =+$H$1/3 -> 7.6666667 | C4: =+B4*1000000 -> 7666666.7
A6: Ağlar | B6: Ağ göz açıklığı (mm) | C6: Ağ uzunluğu (m) | D6: Derinlik Göz Sayısı (adet) | E6: Ağın Derinliği (m) | F6: Ağın Alanı (m2) | G6: Tüm Ağların Alanı (m2)
A7: 1 | B7: =+Sayfa2!D5 -> 70 | C7: =+Sayfa2!B5 -> 200 | E7: =+Sayfa2!C5 -> 10 | F7: =C7*E7 -> 2000 | G7: =SUM(F7:F9) -> 3750
A8: 2 | B8: =+Sayfa2!H5 -> 70 | C8: =+Sayfa2!F5 -> 200 | E8: =+Sayfa2!G5 -> 5 | F8: =C8*E8 -> 1000
A9: 3 | B9: =+Sayfa2!L5 -> 70 | C9: =+Sayfa2!J5 -> 150 | E9: =+Sayfa2!K5 -> 5 | F9: =C9*E9 -> 750
B10: =+ROUND(AVERAGE(B7:B9),0) -> 70
D11: Avlanan Miktarlar (kg) | G11: Birim alandaki stok yoğunluğu (kg/m2) | J11: Toplam Stok (kg)
A12: Avcılık No: | B12: Avcılık Tarihi | C12: Ağların alanı (m2) | D12: 1. İst. 1.Ağ | E12: 2. ist.1.Ağ | F12: 3. ist.1.Ağ | G12: 1. İst. 1.Ağ | H12: 2. ist.1.Ağ | I12: 3. ist.1.Ağ | J12: 1. İst. | K12: 2. ist. | L12: 3. ist.
B13: =+Sayfa2!A3 -> 03.12.2021 | D13: =+Sayfa2!B18 -> 4.52 | E13: =+Sayfa2!F18 -> 7.4 | F13: =+Sayfa2!J18 -> 5.36 | G13: =D13/$F$7 -> 0.00226 | H13: =E13/$F$8 -> 0.0074 | I13: =F13/$F$9 -> 0.0071466667 | J13: =G13*$C2 -> 17326.667 | K13: =H13*$C2 -> 56733.333 | L13: =I13*$C2 -> 54791.111
B14: =+Sayfa2!A21 -> 07.12.2021 | D14: =+Sayfa2!B36 -> 4.586 | E14: =+Sayfa2!F36 -> 5.3 | F14: =+Sayfa2!J36 -> 7.09 | G14: =D14/$F$7 -> 0.002293 | H14: =E14/$F$8 -> 0.0053 | I14: =F14/$F$9 -> 0.0094533333 | J14: =G14*$C3 -> 17579.667 | K14: =H14*$C3 -> 40633.333 | L14: =I14*$C3 -> 72475.556
B15: =+Sayfa2!A39 -> 08.12.2021 | D15: =+Sayfa2!B54 -> 4.91 | E15: =+Sayfa2!F54 -> 3 | F15: =+Sayfa2!J54 -> 2.44 | G15: =D15/$F$7 -> 0.002455 | H15: =E15/$F$8 -> 0.003 | I15: =F15/$F$9 -> 0.0032533333 | J15: =G15*$C4 -> 18821.667 | K15: =H15*$C4 -> 23000 | L15: =I15*$C4 -> 24942.222
A23: Ortalama (kg) | D23: =AVERAGE(D13:D22) -> 4.672 | E23: =AVERAGE(E13:E22) -> 5.2333333 | F23: =AVERAGE(F13:F22) -> 4.9633333 | G23: =+AVERAGE(G13:G22) -> 0.002336 | H23: =+AVERAGE(H13:H22) -> 0.0052333333 | I23: =+AVERAGE(I13:I22) -> 0.0066177778 | J23: =+AVERAGE(J13:J22) -> 17909.333 | K23: =+AVERAGE(K13:K22) -> 40122.222 | L23: =+AVERAGE(L13:L22) -> 50736.296
A24: Toplam Biyomas (ton) | J24: =SUM(J23:L23)/1000 -> 108.76785
A27: 0.866 | B27: 0,5 donam faktörüyle donanmış bir ağın derinliğini hesaplamak için kullanılan sabit katsayı | F27: E= 0,3 ile 0,6 arasında tercih edilebilir, ideal değeri 0,5 olarak kabul edilir
F28: E=0,5 | G28: alınırsa | H28: Avlanabilir Stok (kiralamaya esas) = | K28: =J24*0.5 -> 54.383926 | L28: =+ROUND(K28,4) -> 54.3839
F29: E=0,3 | G29: alınırsa | H29: Avlanabilir Stok (kiralamaya esas) = | K29: =J24*0.3 -> 32.630356 | L29: =+ROUND(K29,4) -> 32.6304
F30: E=0,4 | G30: alınırsa | H30: Avlanabilir Stok (kiralamaya esas) = | K30: =J24*0.4 -> 43.507141
C33: Avlanan Miktarlar (kg) | D33: Türlerin toplam avdaki oranları
A35: Sazan | B35: C.carpio | C35: =+SUMIFS(Sayfa2!$B:$B,Sayfa2!A:A,A35)+SUMIFS(Sayfa2!F:F,Sayfa2!E:E,A35)+SUMIFS(Sayfa2!J:J,Sayfa2!I:I,A35) -> 18.136 | D35: =C35/C$42*100 -> 51.601889 | E35: =+IF(C35>0.01,1,0) -> 1
A36: Yayın | B36: S. glanis | C36: =+SUMIFS(Sayfa2!$B:$B,Sayfa2!A:A,A36)+SUMIFS(Sayfa2!F:F,Sayfa2!E:E,A36)+SUMIFS(Sayfa2!J:J,Sayfa2!I:I,A36) -> 1.85 | D36: =C36/C$42*100 -> 5.2637569 | E36: =+IF(C36>0.01,1,0) -> 1
A37: Sudak | B37: S. lucioperca | C37: =+SUMIFS(Sayfa2!$B:$B,Sayfa2!A:A,A37)+SUMIFS(Sayfa2!F:F,Sayfa2!E:E,A37)+SUMIFS(Sayfa2!J:J,Sayfa2!I:I,A37) -> 4.15 | D37: =C37/C$42*100 -> 11.807887 | E37: =+IF(C37>0.01,1,0) -> 1
A38: Siraz | B38: Capoeta sp. | C38: =+SUMIFS(Sayfa2!$B:$B,Sayfa2!A:A,A38)+SUMIFS(Sayfa2!F:F,Sayfa2!E:E,A38)+SUMIFS(Sayfa2!J:J,Sayfa2!I:I,A38) -> 6.24 | D38: =C38/C$42*100 -> 17.75451 | E38: =+IF(C38>0.01,1,0) -> 1
A39: Tatlısu kefali | B39: S.cephalus | C39: =+SUMIFS(Sayfa2!$B:$B,Sayfa2!A:A,A39)+SUMIFS(Sayfa2!F:F,Sayfa2!E:E,A39)+SUMIFS(Sayfa2!J:J,Sayfa2!I:I,A39) -> 3.19 | D39: =C39/C$42*100 -> 9.0764241 | E39: =+IF(C39>0.01,1,0) -> 1
A40: Bıyıklı balık | B40: Barbus sp. | C40: =+SUMIFS(Sayfa2!$B:$B,Sayfa2!A:A,A40)+SUMIFS(Sayfa2!F:F,Sayfa2!E:E,A40)+SUMIFS(Sayfa2!J:J,Sayfa2!I:I,A40) -> 1.58 | D40: =C40/C$42*100 -> 4.4955329 | E40: =+IF(C40>0.01,1,0) -> 1
A41: Kaya balığı | B41: P.marmoratus | C41: =+SUMIFS(Sayfa2!$B:$B,Sayfa2!A:A,A41)+SUMIFS(Sayfa2!F:F,Sayfa2!E:E,A41)+SUMIFS(Sayfa2!J:J,Sayfa2!I:I,A41) -> 0 | D41: =C41/C$42*100 -> 0 | E41: =+IF(C41>0.01,1,0) -> 0
B42: Toplam | C42: =SUM(C35:C41) -> 35.146 | D42: =SUM(D35:D41) -> 100
A46: Rapor örneği
A48: =CONCATENATE(" ",E1," ","avlak sahasında belirlenen"," ","3 istasyonda"," ",G7," ","m²"," ","ağ alanına sahip"," ","ortalama"," ",B10," ","mm"," ","göz açıklığına sahip"," ",A9," ","adet ", "uzatma ağları kullanılarak"," ",Sayfa2!A3," ","-"," ",Sayfa2!A39," ","tarihleri arasında avcılık operasyonları düzenlenmiştir."," ","Denemeler sonucunda"," ",IF(E35=1,A35," "),",",IF(E36=1,A36," ")," ,",IF(E37=1,A37," ")," ",IF(E38=1,A38," "),",",IF(E39=1,A39," "),",",IF(E40=1,A40," "),",",IF(E41=1,A41," ")," ","türlerinden toplam"," ",C42," ","kg"," ","balık yakalanmış olup toplam avın ağırlığına göre dağılımı ise şu şekildedir."," ",IF(E35=1,B35," ")," ","türü"," ","%"," ",ROUND(C35/C$42*100,2),", ",IF(E36=1,B36," ")," ","türü"," ","%"," ",ROUND(C36/C$42*100,2),", ",IF(E37=1,B37," ")," ","türü"," ","%"," ",ROUND(C37/C$42*100,2)," ","vs. Stok büyüklüğünün tahmininde Avşar ve diğ. (2000)’in önerdiği “Uzatma Ağlarıyla Avcılık Yöntemi”nden yararlanılmıştır. Her bir bölge için hesaplanan toplam stok değerleri tabloda görülmektedir."," ","Ayrıca baraj gölündeki avcılık baskısı dikkate alındığında stoktan yararlanma düzeyinin Gulland (1971), E=0,3"," ","olarak alınması uygun bulunmaktadır. Bu durumda yıllık kiralamaya esas stok miktarı"," ",L29," ","ton/yıl olarak tahmin edilmiştir.") -> Altınkaya Baraj Gölü avlak sahasında belirlenen 3 istasyonda 3750 m² ağ alanına sahip ortalama 70 mm göz açıklığına sahip 3 adet uzatma ağları kullanılarak 03.12.2021 - 08.12.2021 tarihleri arasında avcılık operasyonları düzenlenmiştir. Denemeler sonucunda Sazan,Yayın ,Sudak Siraz,Tatlısu kefali,Bıyıklı balık, türlerinden toplam 35,146 kg balık yakalanmış olup toplam avın ağırlığına göre dağılımı ise şu şekildedir. C.carpio türü % 51,6, S. glanis türü % 5,26, S. lucioperca türü % 11,81 vs. Stok büyüklüğünün tahmininde Avşar ve diğ. (2000)’in önerdiği “Uzatma Ağlarıyla Avcılık Yöntemi”nden yararlanılmıştır. Her bir bölge için hesaplanan toplam stok değerleri tabloda görülmektedir. Ayrıca baraj gölündeki avcılık baskısı dikkate alındığında stoktan yararlanma düzeyinin Gulland (1971), E=0,3 olarak alınması uygun bulunmaktadır. Bu durumda yıllık kiralamaya esas stok miktarı 32,6304 ton/yıl olarak tahmin edilmiştir.
A56: NOT: Sonuçta her bir tür için ayrı bir stok hesaplayacaksak eğer her avcılıkta yakaladığımız balıkların ağırlıkça oranlarını tespit etmemiz lazım. Böylece toplamda şu kadar avcılık yaptık şu akdar kilo balık yakaladık bunun %20 si şu türdendi dolayısıyla tespit ettiğimiz stoktaki oranıda budur diyebiliriz.

Sheet Sayfa1
B1: İstasyonların alanları (km2) | E1: Altınkaya Baraj Gölü | H1: 23 | I1: =+C2+C3+C4 -> 23000000
A2: 1. İst | B2: =+$H$1/3 -> 7.6666667 | C2: =+B2*1000000 -> 7666666.7 | E2: Balıkçı Sayısı | H2: 200
A3: 2. ist | B3: =+$H$1/3 -> 7.6666667 | C3: =+B3*1000000 -> 7666666.7 | E3: Ticari Türler | H3: =+CONCATENATE(B35,",",B36,",",B37,",",B38,",",B39,",",B40," ,",B41," ","vs.") -> C.carpio,S. glanis,S. lucioperca,Capoeta sp.,S.cephalus,Barbus sp. ,P.marmoratus vs.
A4: 3. ist | B4: =+$H$1/3 -> 7.6666667 | C4: =+B4*1000000 -> 7666666.7
A6: Ağlar | B6: Ağ göz açıklığı (mm) | C6: Ağ uzunluğu (m) | D6: Derinlik Göz Sayısı (adet) | E6: Ağın Derinliği (m) | F6: Ağın Alanı (m2) | G6: Tüm Ağların Alanı (m2)
A7: 1 | B7: =+Sayfa2!D5 -> 70 | C7: =+Sayfa2!B5 -> 200 | E7: =+Sayfa2!C5 -> 10 | F7: =C7*E7 -> 2000 | G7: =SUM(F7:F9) -> 3750
A8: 2 | B8: =+Sayfa2!H5 -> 70 | C8: =+Sayfa2!F5 -> 200 | E8: =+Sayfa2!G5 -> 5 | F8: =C8*E8 -> 1000
A9: 3 | B9: =+Sayfa2!L5 -> 70 | C9: =+Sayfa2!J5 -> 150 | E9: =+Sayfa2!K5 -> 5 | F9: =C9*E9 -> 750
B10: =+ROUND(AVERAGE(B7:B9),0) -> 70
D11: Avlanan Miktarlar (kg) | G11: Birim alandaki stok yoğunluğu (kg/m2) | J11: Toplam Stok (kg)
A12: Avcılık No: | B12: Avcılık Tarihi | C12: Ağların alanı (m2) | D12: 1. İst. 1.Ağ | E12: 2. ist.1.Ağ | F12: 3. ist.1.Ağ | G12: 1. İst. 1.Ağ | H12: 2. ist.1.Ağ | I12: 3. ist.1.Ağ | J12: 1. İst. | K12: 2. ist. | L12: 3. ist.
B13: =+Sayfa2!A3 -> 03.12.2021 | D13: =+Sayfa2!B18 -> 4.52 | E13: =+Sayfa2!F18 -> 7.4 | F13: =+Sayfa2!J18 -> 5.36 | G13: =D13/$F$7 -> 0.00226 | H13: =E13/$F$8 -> 0.0074 | I13: =F13/$F$9 -> 0.0071466667 | J13: =G13*$C2 -> 17326.667 | K13: =H13*$C2 -> 56733.333 | L13: =I13*$C2 -> 54791.111
B14: =+Sayfa2!A21 -> 07.12.2021 | D14: =+Sayfa2!B36 -> 4.586 | E14: =+Sayfa2!F36 -> 5.3 | F14: =+Sayfa2!J36 -> 7.09 | G14: =D14/$F$7 -> 0.002293 | H14: =E14/$F$8 -> 0.0053 | I14: =F14/$F$9 -> 0.0094533333 | J14: =G14*$C3 -> 17579.667 | K14: =H14*$C3 -> 40633.333 | L14: =I14*$C3 -> 72475.556
B15: =+Sayfa2!A39 -> 08.12.2021 | D15: =+Sayfa2!B54 -> 4.91 | E15: =+Sayfa2!F54 -> 3 | F15: =+Sayfa2!J54 -> 2.44 | G15: =D15/$F$7 -> 0.002455 | H15: =E15/$F$8 -> 0.003 | I15: =F15/$F$9 -> 0.0032533333 | J15: =G15*$C4 -> 18821.667 | K15: =H15*$C4 -> 23000 | L15: =I15*$C4 -> 24942.222
A23: Ortalama (kg) | D23: =AVERAGE(D13:D22) -> 4.672 | E23: =AVERAGE(E13:E22) -> 5.2333333 | F23: =AVERAGE(F13:F22) -> 4.9633333 | G23: =+AVERAGE(G13:G22) -> 0.002336 | H23: =+AVERAGE(H13:H22) -> 0.0052333333 | I23: =+AVERAGE(I13:I22) -> 0.0066177778 | J23: =+AVERAGE(J13:J22) -> 17909.333 | K23: =+AVERAGE(K13:K22) -> 40122.222 | L23: =+AVERAGE(L13:L22) -> 50736.296
A24: Toplam Biyomas (ton) | J24: =SUM(J23:L23)/1000 -> 108.76785
A27: 0.866 | B27: 0,5 donam faktörüyle donanmış bir ağın derinliğini hesaplamak için kullanılan sabit katsayı | F27: E= 0,3 ile 0,6 arasında tercih edilebilir, ideal değeri 0,5 olarak kabul edilir
F28: E=0,5 | G28: alınırsa | H28: Avlanabilir Stok (kiralamaya esas) = | K28: =J24*0.5 -> 54.383926 | L28: =+ROUND(K28,4) -> 54.3839
F29: E=0,3 | G29: alınırsa | H29: Avlanabilir Stok (kiralamaya esas) = | K29: =J24*0.3 -> 32.630356 | L29: =+ROUND(K29,4) -> 32.6304
F30: E=0,4 | G30: alınırsa | H30: Avlanabilir Stok (kiralamaya esas) = | K30: =J24*0.4 -> 43.507141
C33: Avlanan Miktarlar (kg) | D33: Türlerin toplam avdaki oranları
A35: Sazan | B35: C.carpio | C35: =+SUMIFS(Sayfa2!$B:$B,Sayfa2!A:A,A35)+SUMIFS(Sayfa2!F:F,Sayfa2!E:E,A35)+SUMIFS(Sayfa2!J:J,Sayfa2!I:I,A35) -> 18.136 | D35: =C35/C$42*100 -> 51.601889 | E35: =+IF(C35>0.01,1,0) -> 1
A36: Yayın | B36: S. glanis | C36: =+SUMIFS(Sayfa2!$B:$B,Sayfa2!A:A,A36)+SUMIFS(Sayfa2!F:F,Sayfa2!E:E,A36)+SUMIFS(Sayfa2!J:J,Sayfa2!I:I,A36) -> 1.85 | D36: =C36/C$42*100 -> 5.2637569 | E36: =+IF(C36>0.01,1,0) -> 1
A37: Sudak | B37: S. lucioperca | C37: =+SUMIFS(Sayfa2!$B:$B,Sayfa2!A:A,A37)+SUMIFS(Sayfa2!F:F,Sayfa2!E:E,A37)+SUMIFS(Sayfa2!J:J,Sayfa2!I:I,A37) -> 4.15 | D37: =C37/C$42*100 -> 11.807887 | E37: =+IF(C37>0.01,1,0) -> 1
A38: Siraz | B38: Capoeta sp. | C38: =+SUMIFS(Sayfa2!$B:$B,Sayfa2!A:A,A38)+SUMIFS(Sayfa2!F:F,Sayfa2!E:E,A38)+SUMIFS(Sayfa2!J:J,Sayfa2!I:I,A38) -> 6.24 | D38: =C38/C$42*100 -> 17.75451 | E38: =+IF(C38>0.01,1,0) -> 1
A39: Tatlısu kefali | B39: S.cephalus | C39: =+SUMIFS(Sayfa2!$B:$B,Sayfa2!A:A,A39)+SUMIFS(Sayfa2!F:F,Sayfa2!E:E,A39)+SUMIFS(Sayfa2!J:J,Sayfa2!I:I,A39) -> 3.19 | D39: =C39/C$42*100 -> 9.0764241 | E39: =+IF(C39>0.01,1,0) -> 1
A40: Bıyıklı balık | B40: Barbus sp. | C40: =+SUMIFS(Sayfa2!$B:$B,Sayfa2!A:A,A40)+SUMIFS(Sayfa2!F:F,Sayfa2!E:E,A40)+SUMIFS(Sayfa2!J:J,Sayfa2!I:I,A40) -> 1.58 | D40: =C40/C$42*100 -> 4.4955329 | E40: =+IF(C40>0.01,1,0) -> 1
A41: Kaya balığı | B41: P.marmoratus | C41: =+SUMIFS(Sayfa2!$B:$B,Sayfa2!A:A,A41)+SUMIFS(Sayfa2!F:F,Sayfa2!E:E,A41)+SUMIFS(Sayfa2!J:J,Sayfa2!I:I,A41) -> 0 | D41: =C41/C$42*100 -> 0 | E41: =+IF(C41>0.01,1,0) -> 0
B42: Toplam | C42: =SUM(C35:C41) -> 35.146 | D42: =SUM(D35:D41) -> 100
A46: Rapor örneği
A48: =CONCATENATE(" ",E1," ","avlak sahasında belirlenen"," ","3 istasyonda"," ",G7," ","m²"," ","ağ alanına sahip"," ","ortalama"," ",B10," ","mm"," ","göz açıklığına sahip"," ",A9," ","adet ", "uzatma ağları kullanılarak"," ",Sayfa2!A3," ","-"," ",Sayfa2!A39," ","tarihleri arasında avcılık operasyonları düzenlenmiştir."," ","Denemeler sonucunda"," ",IF(E35=1,A35," "),",",IF(E36=1,A36," ")," ,",IF(E37=1,A37," ")," ",IF(E38=1,A38," "),",",IF(E39=1,A39," "),",",IF(E40=1,A40," "),",",IF(E41=1,A41," ")," ","türlerinden toplam"," ",C42," ","kg"," ","balık yakalanmış olup toplam avın ağırlığına göre dağılımı ise şu şekildedir."," ",IF(E35=1,B35," ")," ","türü"," ","%"," ",ROUND(C35/C$42*100,2),", ",IF(E36=1,B36," ")," ","türü"," ","%"," ",ROUND(C36/C$42*100,2),", ",IF(E37=1,B37," ")," ","türü"," ","%"," ",ROUND(C37/C$42*100,2)," ","vs. Stok büyüklüğünün tahmininde Avşar ve diğ. (2000)’in önerdiği “Uzatma Ağlarıyla Avcılık Yöntemi”nden yararlanılmıştır. Her bir bölge için hesaplanan toplam stok değerleri tabloda görülmektedir."," ","Ayrıca baraj gölündeki avcılık baskısı dikkate alındığında stoktan yararlanma düzeyinin Gulland (1971), E=0,3"," ","olarak alınması uygun bulunmaktadır. Bu durumda yıllık kiralamaya esas stok miktarı"," ",L29," ","ton/yıl olarak tahmin edilmiştir.") -> Altınkaya Baraj Gölü avlak sahasında belirlenen 3 istasyonda 3750 m² ağ alanına sahip ortalama 70 mm göz açıklığına sahip 3 adet uzatma ağları kullanılarak 03.12.2021 - 08.12.2021 tarihleri arasında avcılık operasyonları düzenlenmiştir. Denemeler sonucunda Sazan,Yayın ,Sudak Siraz,Tatlısu kefali,Bıyıklı balık, türlerinden toplam 35,146 kg balık yakalanmış olup toplam avın ağırlığına göre dağılımı ise şu şekildedir. C.carpio türü % 51,6, S. glanis türü % 5,26, S. lucioperca türü % 11,81 vs. Stok büyüklüğünün tahmininde Avşar ve diğ. (2000)’in önerdiği “Uzatma Ağlarıyla Avcılık Yöntemi”nden yararlanılmıştır. Her bir bölge için hesaplanan toplam stok değerleri tabloda görülmektedir. Ayrıca baraj gölündeki avcılık baskısı dikkate alındığında stoktan yararlanma düzeyinin Gulland (1971), E=0,3 olarak alınması uygun bulunmaktadır. Bu durumda yıllık kiralamaya esas stok miktarı 32,6304 ton/yıl olarak tahmin edilmiştir.
A56: NOT: Sonuçta her bir tür için ayrı bir stok hesaplayacaksak eğer her avcılıkta yakaladığımız balıkların ağırlıkça oranlarını tespit etmemiz lazım. Böylece toplamda şu kadar avcılık yaptık şu akdar kilo balık yakaladık bunun %20 si şu türdendi dolayısıyla tespit ettiğimiz stoktaki oranıda budur diyebiliriz.

Sheet Sayfa4
A1: =+Sonuç!A35 -> Sazan | B1: =+SUMIFS(Sayfa2!$B$8:$B$17,Sayfa2!$A$8:$A$17,A1) -> 1.25 | C1: =+SUMIFS(Sayfa2!$F$8:$F$17,Sayfa2!$E$8:$E$17,A1) -> 3.48 | D1: =+SUMIFS(Sayfa2!$J$8:$J$17,Sayfa2!$I$8:$I$17,A1) -> 1.28 | E1: =+SUM(B1:D1) -> 6.01 | I1: =+Sonuç!A35 -> Sazan | J1: =+Sonuç!B35 -> C.carpio | K1: =+Sonuç!$K$29*Sonuç!D35*10 -> 16837.88
A2: =+Sonuç!A36 -> Yayın | B2: =+SUMIFS(Sayfa2!$B$8:$B$17,Sayfa2!$A$8:$A$17,A2) -> 0 | C2: =+SUMIFS(Sayfa2!$F$8:$F$17,Sayfa2!$E$8:$E$17,A2) -> 0 | D2: =+SUMIFS(Sayfa2!$J$8:$J$17,Sayfa2!$I$8:$I$17,A2) -> 0 | E2: =+SUM(B2:D2) -> 0 | I2: =+Sonuç!A36 -> Yayın | J2: =+Sonuç!B36 -> S. glanis | K2: =+Sonuç!$K$29*Sonuç!D36*10 -> 1717.5826
A3: =+Sonuç!A37 -> Sudak | B3: =+SUMIFS(Sayfa2!$B$8:$B$17,Sayfa2!$A$8:$A$17,A3) -> 0 | C3: =+SUMIFS(Sayfa2!$F$8:$F$17,Sayfa2!$E$8:$E$17,A3) -> 2.1 | D3: =+SUMIFS(Sayfa2!$J$8:$J$17,Sayfa2!$I$8:$I$17,A3) -> 0 | E3: =+SUM(B3:D3) -> 2.1 | I3: =+Sonuç!A37 -> Sudak | J3: =+Sonuç!B37 -> S. lucioperca | K3: =+Sonuç!$K$29*Sonuç!D37*10 -> 3852.9555
A4: =+Sonuç!A38 -> Siraz | B4: =+SUMIFS(Sayfa2!$B$8:$B$17,Sayfa2!$A$8:$A$17,A4) -> 0.9 | C4: =+SUMIFS(Sayfa2!$F$8:$F$17,Sayfa2!$E$8:$E$17,A4) -> 0.74 | D4: =+SUMIFS(Sayfa2!$J$8:$J$17,Sayfa2!$I$8:$I$17,A4) -> 0.66 | E4: =+SUM(B4:D4) -> 2.3 | I4: =+Sonuç!A38 -> Siraz | J4: =+Sonuç!B38 -> Capoeta sp. | K4: =+Sonuç!$K$29*Sonuç!D38*10 -> 5793.3597
A5: =+Sonuç!A39 -> Tatlısu kefali | B5: =+SUMIFS(Sayfa2!$B$8:$B$17,Sayfa2!$A$8:$A$17,A5) -> 0.58 | C5: =+SUMIFS(Sayfa2!$F$8:$F$17,Sayfa2!$E$8:$E$17,A5) -> 0 | D5: =+SUMIFS(Sayfa2!$J$8:$J$17,Sayfa2!$I$8:$I$17,A5) -> 0 | E5: =+SUM(B5:D5) -> 0.58 | I5: =+Sonuç!A39 -> Tatlısu kefali | J5: =+Sonuç!B39 -> S.cephalus | K5: =+Sonuç!$K$29*Sonuç!D39*10 -> 2961.6694
A6: =+Sonuç!A40 -> Bıyıklı balık | B6: =+SUMIFS(Sayfa2!$B$8:$B$17,Sayfa2!$A$8:$A$17,A6) -> 0 | C6: =+SUMIFS(Sayfa2!$F$8:$F$17,Sayfa2!$E$8:$E$17,A6) -> 0 | D6: =+SUMIFS(Sayfa2!$J$8:$J$17,Sayfa2!$I$8:$I$17,A6) -> 0.56 | E6: =+SUM(B6:D6) -> 0.56 | I6: =+Sonuç!A40 -> Bıyıklı balık | J6: =+Sonuç!B40 -> Barbus sp. | K6: =+Sonuç!$K$29*Sonuç!D40*10 -> 1466.9084
A7: =+Sonuç!A41 -> Kaya balığı | B7: =+SUMIFS(Sayfa2!$B$8:$B$17,Sayfa2!$A$8:$A$17,A7) -> 0 | C7: =+SUMIFS(Sayfa2!$F$8:$F$17,Sayfa2!$E$8:$E$17,A7) -> 0 | D7: =+SUMIFS(Sayfa2!$J$8:$J$17,Sayfa2!$I$8:$I$17,A7) -> 0 | E7: =+SUM(B7:D7) -> 0 | I7: =+Sonuç!A41 -> Kaya balığı | J7: =+Sonuç!B41 -> P.marmoratus | K7: =+Sonuç!$K$29*Sonuç!D41*10 -> 0
B8: =SUM(B1:B7) -> 2.73 | C8: =SUM(C1:C7) -> 6.32 | D8: =SUM(D1:D7) -> 2.5 | E8: =SUM(E1:E7) -> 11.55 | K8: =SUM(K1:K7) -> 32630.356
A11: =+A1 -> Sazan | B11: =+SUMIFS(Sayfa2!$B$26:$B$35,Sayfa2!$A$26:$A$35,A11) -> 2.786 | C11: =+SUMIFS(Sayfa2!$F$26:$F$35,Sayfa2!$E$26:$E$35,A11) -> 2.74 | D11: =+SUMIFS(Sayfa2!$J$26:$J$35,Sayfa2!$I$26:$I$35,A11) -> 2.73 | E11: =+SUM(B11:D11) -> 8.256
A12: =+A2 -> Yayın | B12: =+SUMIFS(Sayfa2!$B$26:$B$35,Sayfa2!$A$26:$A$35,A12) -> 0 | C12: =+SUMIFS(Sayfa2!$F$26:$F$35,Sayfa2!$E$26:$E$35,A12) -> 0 | D12: =+SUMIFS(Sayfa2!$J$26:$J$35,Sayfa2!$I$26:$I$35,A12) -> 0 | E12: =+SUM(B12:D12) -> 0
A13: =+A3 -> Sudak | B13: =+SUMIFS(Sayfa2!$B$26:$B$35,Sayfa2!$A$26:$A$35,A13) -> 0 | C13: =+SUMIFS(Sayfa2!$F$26:$F$35,Sayfa2!$E$26:$E$35,A13) -> 0 | D13: =+SUMIFS(Sayfa2!$J$26:$J$35,Sayfa2!$I$26:$I$35,A13) -> 2.05 | E13: =+SUM(B13:D13) -> 2.05
A14: =+A4 -> Siraz | B14: =+SUMIFS(Sayfa2!$B$26:$B$35,Sayfa2!$A$26:$A$35,A14) -> 0.9 | C14: =+SUMIFS(Sayfa2!$F$26:$F$35,Sayfa2!$E$26:$E$35,A14) -> 0.93 | D14: =+SUMIFS(Sayfa2!$J$26:$J$35,Sayfa2!$I$26:$I$35,A14) -> 0.71 | E14: =+SUM(B14:D14) -> 2.54
A15: =+A5 -> Tatlısu kefali | B15: =+SUMIFS(Sayfa2!$B$26:$B$35,Sayfa2!$A$26:$A$35,A15) -> 0.63 | C15: =+SUMIFS(Sayfa2!$F$26:$F$35,Sayfa2!$E$26:$E$35,A15) -> 0.6 | D15: =+SUMIFS(Sayfa2!$J$26:$J$35,Sayfa2!$I$26:$I$35,A15) -> 0 | E15: =+SUM(B15:D15) -> 1.23
A16: =+A6 -> Bıyıklı balık | B16: =+SUMIFS(Sayfa2!$B$26:$B$35,Sayfa2!$A$26:$A$35,A16) -> 0 | C16: =+SUMIFS(Sayfa2!$F$26:$F$35,Sayfa2!$E$26:$E$35,A16) -> 0 | D16: =+SUMIFS(Sayfa2!$J$26:$J$35,Sayfa2!$I$26:$I$35,A16) -> 0.53 | E16: =+SUM(B16:D16) -> 0.53
A17: =+A7 -> Kaya balığı | B17: =+SUMIFS(Sayfa2!$B$26:$B$35,Sayfa2!$A$26:$A$35,A17) -> 0 | C17: =+SUMIFS(Sayfa2!$F$26:$F$35,Sayfa2!$E$26:$E$35,A17) -> 0 | D17: =+SUMIFS(Sayfa2!$J$26:$J$35,Sayfa2!$I$26:$I$35,A17) -> 0 | E17: =+SUM(B17:D17) -> 0
B18: =SUM(B11:B17) -> 4.316 | C18: =SUM(C11:C17) -> 4.27 | D18: =SUM(D11:D17) -> 6.02 | E18: =SUM(E11:E17) -> 14.606
A21: =+A11 -> Sazan | B21: =+SUMIFS(Sayfa2!$B$44:$B$53,Sayfa2!$A$44:$A$53,A21) -> 1.31 | C21: =+SUMIFS(Sayfa2!$F$44:$F$53,Sayfa2!$E$44:$E$53,A21) -> 1.31 | D21: =+SUMIFS(Sayfa2!$J$44:$J$53,Sayfa2!$I$44:$I$53,A21) -> 1.25 | E21: =+SUM(B21:D21) -> 3.87
A22: =+A12 -> Yayın | B22: =+SUMIFS(Sayfa2!$B$44:$B$53,Sayfa2!$A$44:$A$53,A22) -> 1.85 | C22: =+SUMIFS(Sayfa2!$F$44:$F$53,Sayfa2!$E$44:$E$53,A22) -> 0 | D22: =+SUMIFS(Sayfa2!$J$44:$J$53,Sayfa2!$I$44:$I$53,A22) -> 0 | E22: =+SUM(B22:D22) -> 1.85
A23: =+A13 -> Sudak | B23: =+SUMIFS(Sayfa2!$B$44:$B$53,Sayfa2!$A$44:$A$53,A23) -> 0 | C23: =+SUMIFS(Sayfa2!$F$44:$F$53,Sayfa2!$E$44:$E$53,A23) -> 0 | D23: =+SUMIFS(Sayfa2!$J$44:$J$53,Sayfa2!$I$44:$I$53,A23) -> 0 | E23: =+SUM(B23:D23) -> 0
A24: =+A14 -> Siraz | B24: =+SUMIFS(Sayfa2!$B$44:$B$53,Sayfa2!$A$44:$A$53,A24) -> 0.47 | C24: =+SUMIFS(Sayfa2!$F$44:$F$53,Sayfa2!$E$44:$E$53,A24) -> 0.46 | D24: =+SUMIFS(Sayfa2!$J$44:$J$53,Sayfa2!$I$44:$I$53,A24) -> 0.47 | E24: =+SUM(B24:D24) -> 1.4
A25: =+A15 -> Tatlısu kefali | B25: =+SUMIFS(Sayfa2!$B$44:$B$53,Sayfa2!$A$44:$A$53,A25) -> 0.66 | C25: =+SUMIFS(Sayfa2!$F$44:$F$53,Sayfa2!$E$44:$E$53,A25) -> 0 | D25: =+SUMIFS(Sayfa2!$J$44:$J$53,Sayfa2!$I$44:$I$53,A25) -> 0.72 | E25: =+SUM(B25:D25) -> 1.38
A26: =+A16 -> Bıyıklı balık | B26: =+SUMIFS(Sayfa2!$B$44:$B$53,Sayfa2!$A$44:$A$53,A26) -> 0 | C26: =+SUMIFS(Sayfa2!$F$44:$F$53,Sayfa2!$E$44:$E$53,A26) -> 0.49 | D26: =+SUMIFS(Sayfa2!$J$44:$J$53,Sayfa2!$I$44:$I$53,A26) -> 0 | E26: =+SUM(B26:D26) -> 0.49
A27: =+A17 -> Kaya balığı | B27: =+SUMIFS(Sayfa2!$B$44:$B$53,Sayfa2!$A$44:$A$53,A27) -> 0 | C27: =+SUMIFS(Sayfa2!$F$44:$F$53,Sayfa2!$E$44:$E$53,A27) -> 0 | D27: =+SUMIFS(Sayfa2!$J$44:$J$53,Sayfa2!$I$44:$I$53,A27) -> 0 | E27: =+SUM(B27:D27) -> 0
B28: =SUM(B21:B27) -> 4.29 | C28: =SUM(C21:C27) -> 2.26 | D28: =SUM(D21:D27) -> 2.44 | E28: =SUM(E21:E27) -> 8.99
E29: =+E8+E18+E28 -> 35.146
